<?xml version='1.0' encoding='utf-8'?>
<robot name="spot">
  <link name="world_link">
  <visual>
  <origin xyz="0 0 0" rpy="0 0 0" />
  <geometry>
  <box size="0.001 0.001 0.001" />
  </geometry>
  </visual>
  </link>
  <joint name="base_joint" type="fixed">
    <origin rpy="0 0 0" xyz="0 0 0.685" />
    <parent link="world_link" />
    <child link="body" />
  </joint>
  <link name="body">
    <visual>
      <origin rpy="0 0 0" xyz="0 0 0" />
      <geometry>
        <mesh filename="meshes/base_simple/visual/body.obj" />
      </geometry>
      <material name="body">
        <color rgba="1 0.8431 0 1" />
      </material>
    </visual>
    <collision>
      <geometry>
        <mesh filename="meshes/base_simple/collision/body.stl" />
      </geometry>
    </collision>
  </link>
  <link name="body_inertia">
    <inertial>
      <origin rpy="0.0 0.0 0.0" xyz="0.006394396536052227 -9.812158532440662e-05 0.0009113792330026627" />
      <mass value="32.86" />
      <inertia ixx="0.13143999874591827" ixy="0.0" ixz="0.0" iyy="0.13143999874591827" iyz="0.0" izz="0.13143999874591827" />
    </inertial>
  </link>
  <joint name="body_inertia_joint" type="fixed">
    <origin rpy="0 0 0" xyz="0 0 0" />
    <parent link="body" />
    <child link="body_inertia" />
  </joint>
  <link name="fl_hip">
    <visual>
      <origin rpy="0 0 0" xyz="0 0 0" />
      <geometry>
        <mesh filename="meshes/base_simple/visual/fl_hip.obj" />
      </geometry>
      <material name="fl_hip">
        <color rgba="0.2 0.2 0.2 1" />
      </material>
    </visual>
    <collision>
      <geometry>
        <mesh filename="meshes/base_simple/collision/fl_hip.stl" />
      </geometry>
    </collision>
    <inertial>
      <origin rpy="-0.716521349312305 0.02956473059648479 0.03655230014702582" xyz="-0.005374345928430557 0.012841847725212574 9.875232353806496e-05" />
      <mass value="1.68" />
      <inertia ixx="0.0021147398873455382" ixy="0.0" ixz="0.0" iyy="0.0018129577956607131" iyz="0.0" izz="0.002265435737304666" />
    </inertial>
  </link>
  <joint name="fl_hx" type="revolute">
    <origin rpy="0 0 0" xyz="0.29785 0.05500 0.00000" />
    <axis xyz="1 0 0" />
    <parent link="body" />
    <child link="fl_hip" />
    <limit effort="1000" lower="-0.78539816339744827899" upper="0.78539816339744827899" velocity="1000.00" />
  </joint>
  <link name="fl_uleg">
    <visual>
      <origin rpy="0 0 0" xyz="0 0 0" />
      <geometry>
        <mesh filename="meshes/base_simple/visual/fl_uleg.obj" />
      </geometry>
      <material name="fl_uleg">
        <color rgba="1 0.8431 0 1" />
      </material>
    </visual>
    <collision>
      <geometry>
        <mesh filename="meshes/base_simple/collision/fl_uleg.stl" />
      </geometry>
    </collision>
    <inertial>
      <origin rpy="-0.26437828203369795 -0.04853174570753804 0.024046963096353124" xyz="0.005142373498529196 -0.0024323679972440004 -0.12100915610790253" />
      <mass value="2.34" />
      <inertia ixx="0.02755964961185679" ixy="0.0" ixz="0.0" iyy="0.027354914287651046" iyz="0.0" izz="0.002848145546743553" />
    </inertial>
  </link>
  <joint name="fl_hy" type="revolute">
    <origin rpy="0 0 0" xyz="0.0 0.11080 0.0" />
    <axis xyz="0 1      0" />
    <parent link="fl_hip" />
    <child link="fl_uleg" />
    <limit effort="1000" lower="-0.89884456477707963539" upper="2.2951079663725435509" velocity="1000.00" />
  </joint>
  <link name="fl_lleg">
    <visual>
      <origin rpy="0 0 0" xyz="0 0 0" />
      <geometry>
        <mesh filename="meshes/base_simple/visual/fl_lleg.obj" />
      </geometry>
      <material name="fl_lleg">
        <color rgba="0.2 0.2 0.2 1" />
      </material>
    </visual>
    <collision>
      <geometry>
        <mesh filename="meshes/base_simple/collision/fl_lleg.stl" />
      </geometry>
    </collision>
    <inertial>
      <origin rpy="-0.007266925694167092 -0.009591807116834161 0.00035255970529224356" xyz="0.00225794012658298 4.607596201822162e-05 -0.1800822913646698" />
      <mass value="0.35" />
      <inertia ixx="0.003999022654901177" ixy="0.0" ixz="0.0" iyy="0.0040503157598010785" iyz="0.0" izz="0.0001493402097647426" />
    </inertial>
  </link>
  <joint name="fl_kn" type="revolute">
    <origin rpy="0 0 0" xyz="0.025 0.000 -0.3200" />
    <axis xyz="0 1 0" />
    <parent link="fl_uleg" />
    <child link="fl_lleg" />
    <limit effort="1000" lower="-2.7929" upper="-0.254402" velocity="1000.00" />
  </joint>
  <link name="fr_hip">
    <visual>
      <origin rpy="0 0 0" xyz="0 0 0" />
      <geometry>
        <mesh filename="meshes/base_simple/visual/fr_hip.obj" />
      </geometry>
      <material name="fr_hip">
        <color rgba="0.2 0.2 0.2 1" />
      </material>
    </visual>
    <collision>
      <geometry>
        <mesh filename="meshes/base_simple/collision/fr_hip.stl" />
      </geometry>
    </collision>
    <inertial>
      <origin rpy="0.7165213493123055 -0.02956473059648479 0.03655230014702582" xyz="-0.005374345928430557 -0.012841847725212574 -9.875232353806496e-05" />
      <mass value="1.68" />
      <inertia ixx="0.0021147398873455382" ixy="0.0" ixz="0.0" iyy="0.0018129577956607131" iyz="0.0" izz="0.002265435737304666" />
    </inertial>
  </link>
  <joint name="fr_hx" type="revolute">
    <origin rpy="0 0 0" xyz="0.29785 -0.05500 0.00000" />
    <axis xyz="1 0 0" />
    <parent link="body" />
    <child link="fr_hip" />
    <limit effort="1000" lower="-0.78539816339744827899" upper="0.78539816339744827899" velocity="1000.00" />
  </joint>
  <link name="fr_uleg">
    <visual>
      <origin rpy="0 0 0" xyz="0 0 0" />
      <geometry>
        <mesh filename="meshes/base_simple/visual/fr_uleg.obj" />
      </geometry>
      <material name="fr_uleg">
        <color rgba="1 0.8431 0 1" />
      </material>
    </visual>
    <collision>
      <geometry>
        <mesh filename="meshes/base_simple/collision/fr_uleg.stl" />
      </geometry>
    </collision>
    <inertial>
      <origin rpy="0.2643905306958363 -0.04853174688302708 -0.024046943559834943" xyz="0.005142373498529196 0.0024323677644133568 -0.12100915610790253" />
      <mass value="2.34" />
      <inertia ixx="0.02755964678927691" ixy="0.0" ixz="0.0" iyy="0.02735491706466737" iyz="0.0" izz="0.0028481453594764797" />
    </inertial>
  </link>
  <joint name="fr_hy" type="revolute">
    <origin rpy="0 0 0" xyz="0.0 -0.11080 0.0" />
    <axis xyz="0  1      0" />
    <parent link="fr_hip" />
    <child link="fr_uleg" />
    <limit effort="1000" lower="-0.898845" upper="2.24363" velocity="1000.00" />
  </joint>
  <link name="fr_lleg">
    <visual>
      <origin rpy="0 0 0" xyz="0 0 0" />
      <geometry>
        <mesh filename="meshes/base_simple/visual/fr_lleg.obj" />
      </geometry>
      <material name="fr_lleg">
        <color rgba="0.2 0.2 0.2 1" />
      </material>
    </visual>
    <collision>
      <geometry>
        <mesh filename="meshes/base_simple/collision/fr_lleg.stl" />
      </geometry>
    </collision>
    <inertial>
      <origin rpy="-0.007266925694167092 -0.009591807116834161 0.00035255970529224356" xyz="0.00225794012658298 4.607596201822162e-05 -0.1800822913646698" />
      <mass value="0.35" />
      <inertia ixx="0.003999022654901177" ixy="0.0" ixz="0.0" iyy="0.0040503157598010785" iyz="0.0" izz="0.0001493402097647426" />
    </inertial>
  </link>
  <joint name="fr_kn" type="revolute">
    <origin rpy="0 0 0" xyz="0.025 0.000 -0.3200" />
    <axis xyz="0 1 0" />
    <parent link="fr_uleg" />
    <child link="fr_lleg" />
    <limit effort="1000" lower="-2.7929" upper="-0.255648" velocity="1000.00" />
  </joint>
  <link name="hl_hip">
    <visual>
      <origin rpy="0 0 0" xyz="0 0 0" />
      <geometry>
        <mesh filename="meshes/base_simple/visual/hl_hip.obj" />
      </geometry>
      <material name="hl_hip">
        <color rgba="0.2 0.2 0.2 1" />
      </material>
    </visual>
    <collision>
      <geometry>
        <mesh filename="meshes/base_simple/collision/hl_hip.stl" />
      </geometry>
    </collision>
    <inertial>
      <origin rpy="0.7165213493123055 0.02956473059648479 -0.03655230014702582" xyz="0.005374345928430557 0.012841847725212574 -9.875232353806496e-05" />
      <mass value="1.68" />
      <inertia ixx="0.0021147398873455382" ixy="0.0" ixz="0.0" iyy="0.0018129577956607131" iyz="0.0" izz="0.002265435737304666" />
    </inertial>
  </link>
  <joint name="hl_hx" type="revolute">
    <origin rpy="0 0 0" xyz="-0.29785 0.05500 0.00000" />
    <axis xyz="1 0 0" />
    <parent link="body" />
    <child link="hl_hip" />
    <limit effort="1000" lower="-0.78539816339744827899" upper="0.78539816339744827899" velocity="1000.00" />
  </joint>
  <link name="hl_uleg">
    <visual>
      <origin rpy="0 0 0" xyz="0 0 0" />
      <geometry>
        <mesh filename="meshes/base_simple/visual/hl_uleg.obj" />
      </geometry>
      <material name="hl_uleg">
        <color rgba="1 0.8431 0 1" />
      </material>
    </visual>
    <collision>
      <geometry>
        <mesh filename="meshes/base_simple/collision/hl_uleg.stl" />
      </geometry>
    </collision>
    <inertial>
      <origin rpy="-0.26437828203369795 -0.04853174570753804 0.024046963096353124" xyz="0.005142373498529196 -0.0024323679972440004 -0.12100915610790253" />
      <mass value="2.34" />
      <inertia ixx="0.02755964961185679" ixy="0.0" ixz="0.0" iyy="0.027354914287651046" iyz="0.0" izz="0.002848145546743553" />
    </inertial>
  </link>
  <joint name="hl_hy" type="revolute">
    <origin rpy="0 0 0" xyz="0.0 0.11080 0.0" />
    <axis xyz="0 1      0" />
    <parent link="hl_hip" />
    <child link="hl_uleg" />
    <limit effort="1000" lower="-0.89884456477707963539" upper="2.2951079663725435509" velocity="1000.00" />
  </joint>
  <link name="hl_lleg">
    <visual>
      <origin rpy="0 0 0" xyz="0 0 0" />
      <geometry>
        <mesh filename="meshes/base_simple/visual/hl_lleg.obj" />
      </geometry>
      <material name="hl_lleg">
        <color rgba="0.2 0.2 0.2 1" />
      </material>
    </visual>
    <collision>
      <geometry>
        <mesh filename="meshes/base_simple/collision/hl_lleg.stl" />
      </geometry>
    </collision>
    <inertial>
      <origin rpy="-0.007266925694167092 -0.009591807116834161 0.00035255970529224356" xyz="0.00225794012658298 4.607596201822162e-05 -0.1800822913646698" />
      <mass value="0.35" />
      <inertia ixx="0.003999022654901177" ixy="0.0" ixz="0.0" iyy="0.0040503157598010785" iyz="0.0" izz="0.0001493402097647426" />
    </inertial>
  </link>
  <joint name="hl_kn" type="revolute">
    <origin rpy="0 0 0" xyz="0.025 0.000 -0.3200" />
    <axis xyz="0 1 0" />
    <parent link="hl_uleg" />
    <child link="hl_lleg" />
    <limit effort="1000" lower="-2.7929" upper="-0.247067" velocity="1000.00" />
  </joint>
  <link name="hr_hip">
    <visual>
      <origin rpy="0 0 0" xyz="0 0 0" />
      <geometry>
        <mesh filename="meshes/base_simple/visual/hr_hip.obj" />
      </geometry>
      <material name="hr_hip">
        <color rgba="0.2 0.2 0.2 1" />
      </material>
    </visual>
    <collision>
      <geometry>
        <mesh filename="meshes/base_simple/collision/hr_hip.stl" />
      </geometry>
    </collision>
    <inertial>
      <origin rpy="-0.716521349312305 -0.02956473059648479 -0.03655230014702582" xyz="0.005374345928430557 -0.012841847725212574 9.875232353806496e-05" />
      <mass value="1.68" />
      <inertia ixx="0.0021147398873455382" ixy="0.0" ixz="0.0" iyy="0.0018129577956607131" iyz="0.0" izz="0.002265435737304666" />
    </inertial>
  </link>
  <joint name="hr_hx" type="revolute">
    <origin rpy="0 0 0" xyz="-0.29785 -0.05500 0.00000" />
    <axis xyz="1 0 0" />
    <parent link="body" />
    <child link="hr_hip" />
    <limit effort="1000" lower="-0.78539816339744827899" upper="0.78539816339744827899" velocity="1000.00" />
  </joint>
  <link name="hr_uleg">
    <visual>
      <origin rpy="0 0 0" xyz="0 0 0" />
      <geometry>
        <mesh filename="meshes/base_simple/visual/hr_uleg.obj" />
      </geometry>
      <material name="hr_uleg">
        <color rgba="1 0.8431 0 1" />
      </material>
    </visual>
    <collision>
      <geometry>
        <mesh filename="meshes/base_simple/collision/hr_uleg.stl" />
      </geometry>
    </collision>
    <inertial>
      <origin rpy="0.2643905306958363 -0.04853174688302708 -0.024046943559834943" xyz="0.005142373498529196 0.0024323677644133568 -0.12100915610790253" />
      <mass value="2.34" />
      <inertia ixx="0.02755964678927691" ixy="0.0" ixz="0.0" iyy="0.02735491706466737" iyz="0.0" izz="0.0028481453594764797" />
    </inertial>
  </link>
  <joint name="hr_hy" type="revolute">
    <origin rpy="0 0 0" xyz="0.0 -0.11080 0.0" />
    <axis xyz="0  1      0" />
    <parent link="hr_hip" />
    <child link="hr_uleg" />
    <limit effort="1000" lower="-0.89884456477707963539" upper="2.2951079663725435509" velocity="1000.00" />
  </joint>
  <link name="hr_lleg">
    <visual>
      <origin rpy="0 0 0" xyz="0 0 0" />
      <geometry>
        <mesh filename="meshes/base_simple/visual/hr_lleg.obj" />
      </geometry>
      <material name="hr_lleg">
        <color rgba="0.2 0.2 0.2 1" />
      </material>
    </visual>
    <collision>
      <geometry>
        <mesh filename="meshes/base_simple/collision/hr_lleg.stl" />
      </geometry>
    </collision>
    <inertial>
      <origin rpy="-0.007266925694167092 -0.009591807116834161 0.00035255970529224356" xyz="0.00225794012658298 4.607596201822162e-05 -0.1800822913646698" />
      <mass value="0.35" />
      <inertia ixx="0.003999022654901177" ixy="0.0" ixz="0.0" iyy="0.0040503157598010785" iyz="0.0" izz="0.0001493402097647426" />
    </inertial>
  </link>
  <joint name="hr_kn" type="revolute">
    <origin rpy="0 0 0" xyz="0.025 0.000 -0.3200" />
    <axis xyz="0 1 0" />
    <parent link="hr_uleg" />
    <child link="hr_lleg" />
    <limit effort="1000" lower="-2.7929" upper="-0.248282" velocity="1000.00" />
  </joint>
  <link name="arm_link_sh0">
    <visual>
      <origin xyz="0 0 0" rpy="0 0 0" />
      <geometry>
        <mesh filename="meshes/arm/visual/arm_link_sh0.obj" />
      </geometry>
      <material name="arm_link_sh0"> <color rgba="0.2 0.2 0.2 1" /></material>  
    </visual>
    <collision>
      <geometry>
        <mesh filename="meshes/arm/collision/arm_link_sh0.stl" />
      </geometry>
    </collision>
    <inertial>
      <origin rpy="0.0013490340912847287 -0.15433618253071657 0.0066354181456347305" xyz="-0.012372709810733795 -4.5211403630673885e-05 -0.02103196457028389" />
      <mass value="2.3364000000000003" />
      <inertia ixx="0.009014303010689815" ixy="0.0" ixz="0.0" iyy="0.005835102417829581" iyz="0.0" izz="0.00778747846359954" />
    </inertial>
  </link>
  <joint name="arm_sh0" type="revolute">
    <origin xyz="0.292 0.0 0.188" rpy="0 0 0" />
    <axis xyz="0 0 1" />
    <parent link="body" />
    <child link="arm_link_sh0" />
    <limit effort="1000" velocity="1000.00" lower="-2.61799387799149441136" upper="3.14159265358979311599" />
  </joint>

  <link name="arm_link_sh1">
    <visual>
      <origin xyz="0 0 0" rpy="0 0 0" />
      <geometry>
        <mesh filename="meshes/arm/visual/arm_link_sh1.obj" />
      </geometry>
      <material name="arm_link_sh1"> <color rgba="0.2 0.2 0.2 1" /></material>
    </visual>
    <collision>
      <geometry>
        <mesh filename="meshes/arm/collision/arm_link_sh1.stl" />
      </geometry>
    </collision>
    <inertial>
      <origin rpy="0.009910032200701302 -0.5123007314267984 0.002209016500439809" xyz="2.4176391889341176e-05 2.4116111490002368e-06 -1.0059113265015185e-05" />
      <mass value="0.2596" />
      <inertia ixx="0.00020292766231464653" ixy="0.0" ixz="0.0" iyy="0.00017078637725384855" iyz="0.0" izz="0.00020384964230406682" />
    </inertial>
  </link>
  <joint name="arm_sh1" type="revolute">
    <origin xyz="0.0 0.0 0.0" rpy="0 0 0" />
    <axis xyz="0 1 0" />
    <parent link="arm_link_sh0" />
    <child link="arm_link_sh1" />
    
    <limit effort="1000" velocity="1000.00" lower="-3.14159265358979311599" upper="0.52359877559829881565" />
  </joint>
  
  <link name="arm_link_hr0">
    <visual>
      <origin xyz="0 0 0" rpy="0 0 0" />
      <geometry>
        <mesh filename="meshes/arm/visual/arm_link_hr0.obj" />
      </geometry>
      <material name="arm_link_hr0"> <color rgba="0.2 0.2 0.2 1" /></material> 
    </visual>
    <collision>
      <geometry>
        <mesh filename="meshes/arm/collision/arm_link_hr0.stl" />
      </geometry>
    </collision>
    <inertial>
      <origin rpy="-0.01179850657706405 0.0002834144901480151 -0.02372295500868482" xyz="0.17047011852264404 -0.0019251034827902913 4.483893280848861e-05" />
      <mass value="1e-06" />
      <inertia ixx="6.312631747339145e-10" ixy="0.0" ixz="0.0" iyy="1.1487063558949979e-08" iyz="0.0" izz="1.161105128440526e-08" />
    </inertial>
  </link>
  <joint name="arm_hr0" type="fixed">
    <origin xyz="0.0 0.0 0.0" rpy="0 0 0" />
    <axis xyz="1 0 0" />
    <parent link="arm_link_sh1" />
    <child link="arm_link_hr0" />
    <limit effort="1000" velocity="1000.00" lower="-1e6" upper="1e6" />
  </joint>

  <link name="arm_link_el0">
    <visual>
      <origin xyz="0 0 0" rpy="0 0 0" />
      <geometry>
        <mesh filename="meshes/arm/visual/arm_link_el0.obj" />
      </geometry>
      <material name="arm_link_el0"> <color rgba="0.2 0.2 0.2 1" /></material>  
    </visual>
    <collision>
      <geometry>
        <mesh filename="meshes/arm/collision/arm_link_el0.stl" />
      </geometry>
    </collision>
    <inertial>
      <origin rpy="-0.004185887288594259 -0.6136269547775202 -0.0004619387581783485" xyz="0.0553741455078125 0.00023603376757819206 0.04827198013663292" />
      <mass value="0.725" />
      <inertia ixx="0.0008215365829160558" ixy="0.0" ixz="0.0" iyy="0.0020047889807066404" iyz="0.0" izz="0.0019722797759789395" />
    </inertial>
  </link>
  <joint name="arm_el0" type="revolute">
    <origin xyz="0.3385 0 0" rpy="0 0 0" />
    <axis xyz="0 1 0" />
    <parent link="arm_link_hr0" />
    <child link="arm_link_el0" />
    <limit effort="1000" velocity="1000.00" lower="0" upper="3.14159265358979311599" />
  </joint>

  <link name="arm_link_el1">
    <visual>
      <origin xyz="0 0 0" rpy="0 0 0" />
      <geometry>
        <mesh filename="meshes/arm/visual/arm_link_el1.obj" />
      </geometry>
      <material name="arm_link_el1"> <color rgba="0.2 0.2 0.2 1" /></material>
    </visual>
    <collision>
      <geometry>
        <mesh filename="meshes/arm/collision/arm_link_el1.stl" />
      </geometry>
    </collision>
    <inertial>
      <origin rpy="-0.15027374227250867 -0.0007874585461915551 0.003728225436950172" xyz="-0.1257835328578949 -0.013684478588402271 0.00010157923679798841" />
      <mass value="0.725" />
      <inertia ixx="0.0006254807525240598" ixy="0.0" ixz="0.0" iyy="0.004402454711936095" iyz="0.0" izz="0.004515915146038191" />
    </inertial>
  </link>
  <joint name="arm_el1" type="revolute">
    <origin xyz="0.40330 0.0 0.0750" rpy="0 0 0" />
    <axis xyz="1 0 0" />
    <parent link="arm_link_el0" />
    <child link="arm_link_el1" />
    <limit effort="1000" velocity="1000.00" lower="-2.79252680319092716487" upper="2.79252680319092716487" />
  </joint>

  <link name="arm_link_wr0">
    <visual>
      <origin xyz="0 0 0" rpy="0 0 0" />
      <geometry>
        <mesh filename="meshes/arm/visual/arm_link_wr0.obj" />
      </geometry>
      <material name="arm_link_wr0"> <color rgba="0.2 0.2 0.2 1" /></material>
    </visual>
    <collision>
      <geometry>
        <mesh filename="meshes/arm/collision/arm_link_wr0.stl" />
      </geometry>
    </collision>
    <inertial>
      <origin rpy="-0.4951534907966386 0.0033720434077784134 0.020027599337697932" xyz="0.008210677653551102 -0.012051000259816647 3.143483627354726e-05" />
      <mass value="0.98" />
      <inertia ixx="0.0009851320696685427" ixy="0.0" ixz="0.0" iyy="0.0008916145765810678" iyz="0.0" izz="0.0012354892751854467" />
    </inertial>
  </link>
  <joint name="arm_wr0" type="revolute">
    <origin xyz="0.0 0.0 0.0" rpy="0 0 0" />
    <axis xyz="0 1 0" />
    <parent link="arm_link_el1" />
    <child link="arm_link_wr0" />
    <limit effort="1000" velocity="1000.00" lower="-1.83259571459404613236" upper="1.83259571459404613236" />
  </joint>

  <link name="arm_link_wr1">
    <visual>
      <origin xyz="0 0 0" rpy="0 0 0" />
      <geometry>
        <mesh filename="meshes/arm/visual/arm_link_wr1.obj" />
      </geometry>
      <material name="arm_link_wr1"> <color rgba="0.2 0.2 0.2 1" /></material>
    </visual>
    <collision>
      <geometry>
        <mesh filename="meshes/arm/collision/arm_link_wr1.stl" />
      </geometry>
    </collision>
    <inertial>
      <origin rpy="0.006393076449033863 0.2928526604761865 -0.022814984050994802" xyz="0.12516802549362183 0.00010137435310753062 -0.013997982256114483" />
      <mass value="0.785" />
      <inertia ixx="0.00076741362048185" ixy="0.0" ixz="0.0" iyy="0.0017628124054271809" iyz="0.0" izz="0.0016818105865345951" />
    </inertial>
  </link>
  <joint name="arm_wr1" type="revolute">
    <origin xyz="0.0 0.0 0.0" rpy="0 0 0" />
    <axis xyz="1 0 0" />
    <parent link="arm_link_wr0" />
    <child link="arm_link_wr1" />
    <limit effort="1000" velocity="1000.00" lower="-2.87979326579064354163" upper="2.87979326579064354163" />
  </joint>
  
  <link name="arm_link_fngr">
    <visual>
      <origin xyz="0 0 0" rpy="0 0 0" />
      <geometry>
        <mesh filename="meshes/arm/visual/arm_link_fngr.obj" />
      </geometry>
      <material name="arm_link_fngr"> <color rgba="0.2 0.2 0.2 1" /></material>
    </visual>
    <collision>
      <geometry>
        <mesh filename="meshes/arm/collision/arm_link_fngr.stl" />
      </geometry>
    </collision>
    <inertial>
      <origin rpy="0.0003416659657240473 0.3751670012784243 -0.004058661249495721" xyz="0.04787873849272728 -0.00020676758140325546 -0.01628788933157921" />
      <mass value="0.2" />
      <inertia ixx="0.0001439963634171048" ixy="0.0" ixz="0.0" iyy="0.0003007126997998294" iyz="0.0" izz="0.0003912783268020657" />
    </inertial>
  </link>
  <joint name="arm_f1x" type="revolute">
    <origin xyz="0.11745 0 0.014820" rpy="0 0 0" />
    <axis xyz="0.0 1.0 0.0" />
    <parent link="arm_link_wr1" />
    <child link="arm_link_fngr" />
    <limit effort="1000" velocity="1000.00" lower="-1.57" upper="0.0" />
  </joint>
  <link name="arm_end_effector_link" />
  <joint name="end_effector_joint" type="fixed">
    <origin rpy="-1.5707963267948966 0. 1.5707963267948966" xyz="0.25 0.0 0.0" />
    <parent link="arm_link_wr1" />
    <child link="arm_end_effector_link" />
  </joint>
<link name="hand_frame"><inertial><origin xyz="0 0 0" rpy="0 0 0" /><mass value="0.1" /><inertia ixx="0.01" ixy="0" ixz="0" iyy="0.01" iyz="0" izz="0.01" /></inertial></link><joint name="hand_frame_joint" type="fixed"><parent link="arm_link_wr1" /><child link="hand_frame" /><origin xyz="0.19557 0.0 0.0" rpy="0 0 0" /></joint></robot>