<?xml version="1.0" ?>
<robot name="two_link_robot">

  <!-- Base link -->
  <link name="base_link">
    <inertial>
      <origin xyz="0 0 0" />
      <mass value="1.0" />
      <inertia ixx="0.1" ixy="0.0" ixz="0.0" iyy="0.1" iyz="0.0" izz="0.1" />
    </inertial>
    <visual>
      <origin xyz="0 0 0" rpy="0 0 0"/>
      <geometry>
        <cylinder radius="0.1" length="0.2"/>
      </geometry>
      <material name="blue">
        <color rgba="0 0 1 1"/>
      </material>
    </visual>
    <collision>
      <origin xyz="0 0 0" rpy="0 0 0"/>
      <geometry>
        <cylinder radius="0.1" length="0.2"/>
      </geometry>
    </collision>
  </link>

  <!-- First joint (continuous) -->
  <joint name="joint1" type="continuous">
    <parent link="base_link"/>
    <child link="link1"/>
    <origin xyz="0 0 0.1" rpy="0 0 0"/>
    <axis xyz="0 0 1"/>
  </joint>

  <!-- First link -->
  <link name="link1">
    <inertial>
      <origin xyz="0 0 0.25" />
      <mass value="1.0" />
      <inertia ixx="0.1" ixy="0.0" ixz="0.0" iyy="0.1" iyz="0.0" izz="0.1" />
    </inertial>
    <visual>
      <origin xyz="0 0 0.25" rpy="0 0 0"/>
      <geometry>
        <box size="0.05 0.05 0.5"/>
      </geometry>
      <material name="green">
        <color rgba="0 1 0 1"/>
      </material>
    </visual>
    <collision>
      <origin xyz="0 0 0.25" rpy="0 0 0"/>
      <geometry>
        <box size="0.05 0.05 0.5"/>
      </geometry>
    </collision>
  </link>

  <!-- Second joint (revolute) -->
  <joint name="joint2" type="revolute">
    <parent link="link1"/>
    <child link="link2"/>
    <origin xyz="0.0 0 0.5" rpy="0 0 0"/>
    <axis xyz="0 1 0"/>
    <limit lower="-0.5" upper="0.5" effort="10.0" velocity="1.0"/>
  </joint>

  <!-- Second link -->
  <link name="link2">
    <inertial>
      <origin xyz="0.25 0 0" />
      <mass value="1.0" />
      <inertia ixx="0.1" ixy="0.0" ixz="0.0" iyy="0.1" iyz="0.0" izz="0.1" />
    </inertial>
    <visual>
      <origin xyz="0.25 0 0" rpy="0 0 0"/>
      <geometry>
        <box size="0.5 0.05 0.05"/>
      </geometry>
      <material name="red">
        <color rgba="1 0 0 1"/>
      </material>
    </visual>
    <collision>
      <origin xyz="0.25 0 0" rpy="0 0 0"/>
      <geometry>
        <box size="0.5 0.05 0.05"/>
      </geometry>
    </collision>
  </link>

  <!-- End effector joint (fixed) -->
  <joint name="end_effector" type="fixed">
    <origin xyz="0.5 0 0" rpy="0 1.5708 0"/>
    <parent link="link2"/>
    <child link="end_effector_link"/>
    <axis xyz="0 0 0"/>
  </joint>

  <!-- End effector link -->
  <link name="end_effector_link">
    <inertial>
      <origin xyz="0.5 0 0" rpy="0 1.5708 0"/>
      <mass value="0"/>
      <inertia ixx="0" ixy="0" ixz="0" iyy="0" iyz="0" izz="0"/>
    </inertial>
  </link>

</robot>
