<?xml version="1.0" ?>
<!-- Adapted from assistive-gym -->
<robot name="assistive-human-extracted">
  <link name="base_link">
    <visual>
      <origin xyz="0.0 0.0 0.0" rpy="-0.0 1.5707963267948966 0.0"/>
      <geometry>
        <cylinder radius="0.127" length="0.056"/>
      </geometry>
      <material name="color-171-128-85-255">
        <color rgba="0.672940731048584 0.504705548286438 0.336470365524292 1.0"/>
      </material>
    </visual>
    <collision>
      <origin xyz="0.0 0.0 0.0" rpy="-0.0 1.5707963267948966 0.0"/>
      <geometry>
        <cylinder radius="0.127" length="0.056"/>
      </geometry>
    </collision>
    <inertial>
      <origin xyz="0.0 0.0 0.0" rpy="0.0 -0.0 0.0"/>
      <mass value="0.0"/>
      <inertia ixx="0.0" ixy="0.0" ixz="0.0" iyy="0.0" iyz="0.0" izz="0.0"/>
    </inertial>
  </link>
  <link name="base_link---top-sphere">
    <visual>
      <origin xyz="0 0 0" rpy="0.0 -0.0 0.0"/>
      <geometry>
        <sphere radius="0.127"/>
      </geometry>
      <material name="color-171-128-85-255">
        <color rgba="0.672940731048584 0.504705548286438 0.336470365524292 1.0"/>
      </material>
    </visual>
    <collision>
      <origin xyz="0 0 0" rpy="0.0 -0.0 0.0"/>
      <geometry>
        <sphere radius="0.127"/>
      </geometry>
    </collision>
    <inertial>
      <origin xyz="0 0 0" rpy="0.0 -0.0 0.0"/>
      <mass value="0.0"/>
      <inertia ixx="0" ixy="0.0" ixz="0.0" iyy="0" iyz="0.0" izz="0"/>
    </inertial>
  </link>
  <link name="base_link---bottom-sphere">
    <visual>
      <origin xyz="0 0 0" rpy="0.0 -0.0 0.0"/>
      <geometry>
        <sphere radius="0.127"/>
      </geometry>
      <material name="color-171-128-85-255">
        <color rgba="0.672940731048584 0.504705548286438 0.336470365524292 1.0"/>
      </material>
    </visual>
    <collision>
      <origin xyz="0 0 0" rpy="0.0 -0.0 0.0"/>
      <geometry>
        <sphere radius="0.127"/>
      </geometry>
    </collision>
    <inertial>
      <origin xyz="0 0 0" rpy="0.0 -0.0 0.0"/>
      <mass value="0.0"/>
      <inertia ixx="0" ixy="0.0" ixz="0.0" iyy="0" iyz="0.0" izz="0"/>
    </inertial>
  </link>
  <link name="link1">
    <inertial>
      <origin xyz="0.0 0.0 0.0" rpy="0.0 -0.0 0.0"/>
      <mass value="0.0"/>
      <inertia ixx="0.0" ixy="0.0" ixz="0.0" iyy="0.0" iyz="0.0" izz="0.0"/>
    </inertial>
  </link>
  <link name="link2">
    <inertial>
      <origin xyz="0.0 0.0 0.0" rpy="0.0 -0.0 0.0"/>
      <mass value="0.0"/>
      <inertia ixx="0.0" ixy="0.0" ixz="0.0" iyy="0.0" iyz="0.0" izz="0.0"/>
    </inertial>
  </link>
  <link name="link3">
    <visual>
      <origin xyz="-0.0853875 0.0 0.0" rpy="-0.0 1.5707963267948966 0.0"/>
      <geometry>
        <cylinder radius="0.106" length="0.031625"/>
      </geometry>
      <material name="color-171-128-85-255">
        <color rgba="0.672940731048584 0.504705548286438 0.336470365524292 1.0"/>
      </material>
    </visual>
    <collision>
      <origin xyz="-0.08538749814033508 0.0 0.0" rpy="-0.0 1.5707963267948966 0.0"/>
      <geometry>
        <cylinder radius="0.106" length="0.031625"/>
      </geometry>
    </collision>
    <inertial>
      <origin xyz="0.0 0.0 0.0" rpy="0.0 -0.0 0.0"/>
      <mass value="0.0"/>
      <inertia ixx="0.0" ixy="0.0" ixz="0.0" iyy="0.0" iyz="0.0" izz="0.0"/>
    </inertial>
  </link>
  <link name="link3---top-sphere">
    <visual>
      <origin xyz="0 0 0" rpy="0.0 -0.0 0.0"/>
      <geometry>
        <sphere radius="0.106"/>
      </geometry>
      <material name="color-171-128-85-255">
        <color rgba="0.672940731048584 0.504705548286438 0.336470365524292 1.0"/>
      </material>
    </visual>
    <collision>
      <origin xyz="0.0 0.0 0.0" rpy="0.0 -0.0 0.0"/>
      <geometry>
        <sphere radius="0.106"/>
      </geometry>
    </collision>
    <inertial>
      <origin xyz="0 0 0" rpy="0.0 -0.0 0.0"/>
      <mass value="0.0"/>
      <inertia ixx="0" ixy="0.0" ixz="0.0" iyy="0" iyz="0.0" izz="0"/>
    </inertial>
  </link>
  <link name="link3---bottom-sphere">
    <visual>
      <origin xyz="0 0 0" rpy="0.0 -0.0 0.0"/>
      <geometry>
        <sphere radius="0.106"/>
      </geometry>
      <material name="color-171-128-85-255">
        <color rgba="0.672940731048584 0.504705548286438 0.336470365524292 1.0"/>
      </material>
    </visual>
    <collision>
      <origin xyz="0.0 0.0 0.0" rpy="0.0 -0.0 0.0"/>
      <geometry>
        <sphere radius="0.106"/>
      </geometry>
    </collision>
    <inertial>
      <origin xyz="0 0 0" rpy="0.0 -0.0 0.0"/>
      <mass value="0.0"/>
      <inertia ixx="0" ixy="0.0" ixz="0.0" iyy="0" iyz="0.0" izz="0"/>
    </inertial>
  </link>
  <link name="link11">
    <inertial>
      <origin xyz="0.0 0.0 0.0" rpy="0.0 -0.0 0.0"/>
      <mass value="0.0"/>
      <inertia ixx="0.0" ixy="0.0" ixz="0.0" iyy="0.0" iyz="0.0" izz="0.0"/>
    </inertial>
  </link>
  <link name="link12">
    <inertial>
      <origin xyz="0.0 0.0 0.0" rpy="0.0 -0.0 0.0"/>
      <mass value="0.0"/>
      <inertia ixx="0.0" ixy="0.0" ixz="0.0" iyy="0.0" iyz="0.0" izz="0.0"/>
    </inertial>
  </link>
  <link name="link13">
    <visual>
      <origin xyz="0.0 0.0 -0.1395" rpy="0.0 -0.0 0.0"/>
      <geometry>
        <cylinder radius="0.043" length="0.279"/>
      </geometry>
      <material name="color-171-128-85-255">
        <color rgba="0.672940731048584 0.504705548286438 0.336470365524292 1.0"/>
      </material>
    </visual>
    <collision>
      <origin xyz="0.0 0.0 -0.13950000703334808" rpy="0.0 -0.0 0.0"/>
      <geometry>
        <cylinder radius="0.043" length="0.279"/>
      </geometry>
    </collision>
    <inertial>
      <origin xyz="0.0 0.0 0.0" rpy="0.0 -0.0 0.0"/>
      <mass value="0.0"/>
      <inertia ixx="0.0" ixy="0.0" ixz="0.0" iyy="0.0" iyz="0.0" izz="0.0"/>
    </inertial>
  </link>
  <link name="link13---top-sphere">
    <visual>
      <origin xyz="0 0 0" rpy="0.0 -0.0 0.0"/>
      <geometry>
        <sphere radius="0.043"/>
      </geometry>
      <material name="color-171-128-85-255">
        <color rgba="0.672940731048584 0.504705548286438 0.336470365524292 1.0"/>
      </material>
    </visual>
    <collision>
      <origin xyz="0.0 0.0 0.0" rpy="0.0 -0.0 0.0"/>
      <geometry>
        <sphere radius="0.043"/>
      </geometry>
    </collision>
    <inertial>
      <origin xyz="0 0 0" rpy="0.0 -0.0 0.0"/>
      <mass value="0.0"/>
      <inertia ixx="0" ixy="0.0" ixz="0.0" iyy="0" iyz="0.0" izz="0"/>
    </inertial>
  </link>
  <link name="link13---bottom-sphere">
    <visual>
      <origin xyz="0 0 0" rpy="0.0 -0.0 0.0"/>
      <geometry>
        <sphere radius="0.043"/>
      </geometry>
      <material name="color-171-128-85-255">
        <color rgba="0.672940731048584 0.504705548286438 0.336470365524292 1.0"/>
      </material>
    </visual>
    <collision>
      <origin xyz="0.0 0.0 0.0" rpy="0.0 -0.0 0.0"/>
      <geometry>
        <sphere radius="0.043"/>
      </geometry>
    </collision>
    <inertial>
      <origin xyz="0 0 0" rpy="0.0 -0.0 0.0"/>
      <mass value="0.0"/>
      <inertia ixx="0" ixy="0.0" ixz="0.0" iyy="0" iyz="0.0" izz="0"/>
    </inertial>
  </link>
  <link name="link14">
    <visual>
      <origin xyz="0.0 0.01 0.0" rpy="0.0 -0.0 0.0"/>
      <geometry>
        <sphere radius="0.038"/>
      </geometry>
      <material name="color-171-128-85-255">
        <color rgba="0.672940731048584 0.504705548286438 0.336470365524292 1.0"/>
      </material>
    </visual>
    <inertial>
      <origin xyz="0.0 0.0 0.0" rpy="0.0 -0.0 0.0"/>
      <mass value="0.0"/>
      <inertia ixx="0.0" ixy="0.0" ixz="0.0" iyy="0.0" iyz="0.0" izz="0.0"/>
    </inertial>
  </link>
  <link name="link15">
    <visual>
      <origin xyz="0.0 0.0 -0.1285" rpy="0.0 -0.0 0.0"/>
      <geometry>
        <cylinder radius="0.033" length="0.257"/>
      </geometry>
      <material name="color-171-128-85-255">
        <color rgba="0.672940731048584 0.504705548286438 0.336470365524292 1.0"/>
      </material>
    </visual>
    <collision>
      <origin xyz="0.0 0.0 -0.12849999964237213" rpy="0.0 -0.0 0.0"/>
      <geometry>
        <cylinder radius="0.033" length="0.257"/>
      </geometry>
    </collision>
    <inertial>
      <origin xyz="0.0 0.0 0.0" rpy="0.0 -0.0 0.0"/>
      <mass value="0.0"/>
      <inertia ixx="0.0" ixy="0.0" ixz="0.0" iyy="0.0" iyz="0.0" izz="0.0"/>
    </inertial>
  </link>
  <link name="link15---top-sphere">
    <visual>
      <origin xyz="0 0 0" rpy="0.0 -0.0 0.0"/>
      <geometry>
        <sphere radius="0.033"/>
      </geometry>
      <material name="color-171-128-85-255">
        <color rgba="0.672940731048584 0.504705548286438 0.336470365524292 1.0"/>
      </material>
    </visual>
    <collision>
      <origin xyz="0.0 0.0 0.0" rpy="0.0 -0.0 0.0"/>
      <geometry>
        <sphere radius="0.033"/>
      </geometry>
    </collision>
    <inertial>
      <origin xyz="0 0 0" rpy="0.0 -0.0 0.0"/>
      <mass value="0.0"/>
      <inertia ixx="0" ixy="0.0" ixz="0.0" iyy="0" iyz="0.0" izz="0"/>
    </inertial>
  </link>
  <link name="link15---bottom-sphere">
    <visual>
      <origin xyz="0 0 0" rpy="0.0 -0.0 0.0"/>
      <geometry>
        <sphere radius="0.033"/>
      </geometry>
      <material name="color-171-128-85-255">
        <color rgba="0.672940731048584 0.504705548286438 0.336470365524292 1.0"/>
      </material>
    </visual>
    <collision>
      <origin xyz="0.0 0.0 0.0" rpy="0.0 -0.0 0.0"/>
      <geometry>
        <sphere radius="0.033"/>
      </geometry>
    </collision>
    <inertial>
      <origin xyz="0 0 0" rpy="0.0 -0.0 0.0"/>
      <mass value="0.0"/>
      <inertia ixx="0" ixy="0.0" ixz="0.0" iyy="0" iyz="0.0" izz="0"/>
    </inertial>
  </link>
  <link name="link16">
    <inertial>
      <origin xyz="0.0 0.0 0.0" rpy="0.0 -0.0 0.0"/>
      <mass value="0.0"/>
      <inertia ixx="0.0" ixy="0.0" ixz="0.0" iyy="0.0" iyz="0.0" izz="0.0"/>
    </inertial>
  </link>
  <link name="link17">
    <visual>
      <origin xyz="0.0 0.0 -0.043" rpy="0.0 -0.0 0.0"/>
      <geometry>
        <sphere radius="0.043"/>
      </geometry>
      <material name="color-171-128-85-255">
        <color rgba="0.672940731048584 0.504705548286438 0.336470365524292 1.0"/>
      </material>
    </visual>
    <collision>
      <origin xyz="0.0 0.0 -0.0430000014603138" rpy="0.0 -0.0 0.0"/>
      <geometry>
        <sphere radius="0.043"/>
      </geometry>
    </collision>
    <inertial>
      <origin xyz="0.0 0.0 0.0" rpy="0.0 -0.0 0.0"/>
      <mass value="0.0"/>
      <inertia ixx="0.0" ixy="0.0" ixz="0.0" iyy="0.0" iyz="0.0" izz="0.0"/>
    </inertial>
  </link>
  <link name="link4">
    <inertial>
      <origin xyz="0.0 0.0 0.0" rpy="0.0 -0.0 0.0"/>
      <mass value="0.0"/>
      <inertia ixx="0.0" ixy="0.0" ixz="0.0" iyy="0.0" iyz="0.0" izz="0.0"/>
    </inertial>
  </link>
  <link name="link5">
    <inertial>
      <origin xyz="0.0 0.0 0.0" rpy="0.0 -0.0 0.0"/>
      <mass value="0.0"/>
      <inertia ixx="0.0" ixy="0.0" ixz="0.0" iyy="0.0" iyz="0.0" izz="0.0"/>
    </inertial>
  </link>
  <link name="link6">
    <visual>
      <origin xyz="0.0853875 0.0 0.0" rpy="-0.0 1.5707963267948966 0.0"/>
      <geometry>
        <cylinder radius="0.106" length="0.031625"/>
      </geometry>
      <material name="color-171-128-85-255">
        <color rgba="0.672940731048584 0.504705548286438 0.336470365524292 1.0"/>
      </material>
    </visual>
    <collision>
      <origin xyz="0.08538749814033508 0.0 0.0" rpy="-0.0 1.5707963267948966 0.0"/>
      <geometry>
        <cylinder radius="0.106" length="0.031625"/>
      </geometry>
    </collision>
    <inertial>
      <origin xyz="0.0 0.0 0.0" rpy="0.0 -0.0 0.0"/>
      <mass value="0.0"/>
      <inertia ixx="0.0" ixy="0.0" ixz="0.0" iyy="0.0" iyz="0.0" izz="0.0"/>
    </inertial>
  </link>
  <link name="link6---top-sphere">
    <visual>
      <origin xyz="0 0 0" rpy="0.0 -0.0 0.0"/>
      <geometry>
        <sphere radius="0.106"/>
      </geometry>
      <material name="color-171-128-85-255">
        <color rgba="0.672940731048584 0.504705548286438 0.336470365524292 1.0"/>
      </material>
    </visual>
    <collision>
      <origin xyz="0.0 0.0 0.0" rpy="0.0 -0.0 0.0"/>
      <geometry>
        <sphere radius="0.106"/>
      </geometry>
    </collision>
    <inertial>
      <origin xyz="0 0 0" rpy="0.0 -0.0 0.0"/>
      <mass value="0.0"/>
      <inertia ixx="0" ixy="0.0" ixz="0.0" iyy="0" iyz="0.0" izz="0"/>
    </inertial>
  </link>
  <link name="link6---bottom-sphere">
    <visual>
      <origin xyz="0 0 0" rpy="0.0 -0.0 0.0"/>
      <geometry>
        <sphere radius="0.106"/>
      </geometry>
      <material name="color-171-128-85-255">
        <color rgba="0.672940731048584 0.504705548286438 0.336470365524292 1.0"/>
      </material>
    </visual>
    <collision>
      <origin xyz="0.0 0.0 0.0" rpy="0.0 -0.0 0.0"/>
      <geometry>
        <sphere radius="0.106"/>
      </geometry>
    </collision>
    <inertial>
      <origin xyz="0 0 0" rpy="0.0 -0.0 0.0"/>
      <mass value="0.0"/>
      <inertia ixx="0" ixy="0.0" ixz="0.0" iyy="0" iyz="0.0" izz="0"/>
    </inertial>
  </link>
  <link name="link18">
    <inertial>
      <origin xyz="0.0 0.0 0.0" rpy="0.0 -0.0 0.0"/>
      <mass value="0.0"/>
      <inertia ixx="0.0" ixy="0.0" ixz="0.0" iyy="0.0" iyz="0.0" izz="0.0"/>
    </inertial>
  </link>
  <link name="link19">
    <inertial>
      <origin xyz="0.0 0.0 0.0" rpy="0.0 -0.0 0.0"/>
      <mass value="0.0"/>
      <inertia ixx="0.0" ixy="0.0" ixz="0.0" iyy="0.0" iyz="0.0" izz="0.0"/>
    </inertial>
  </link>
  <link name="link20">
    <visual>
      <origin xyz="0.0 0.0 -0.1395" rpy="0.0 -0.0 0.0"/>
      <geometry>
        <cylinder radius="0.043" length="0.279"/>
      </geometry>
      <material name="color-171-128-85-255">
        <color rgba="0.672940731048584 0.504705548286438 0.336470365524292 1.0"/>
      </material>
    </visual>
    <collision>
      <origin xyz="0.0 0.0 -0.13950000703334808" rpy="0.0 -0.0 0.0"/>
      <geometry>
        <cylinder radius="0.043" length="0.279"/>
      </geometry>
    </collision>
    <inertial>
      <origin xyz="0.0 0.0 0.0" rpy="0.0 -0.0 0.0"/>
      <mass value="0.0"/>
      <inertia ixx="0.0" ixy="0.0" ixz="0.0" iyy="0.0" iyz="0.0" izz="0.0"/>
    </inertial>
  </link>
  <link name="link20---top-sphere">
    <visual>
      <origin xyz="0 0 0" rpy="0.0 -0.0 0.0"/>
      <geometry>
        <sphere radius="0.043"/>
      </geometry>
      <material name="color-171-128-85-255">
        <color rgba="0.672940731048584 0.504705548286438 0.336470365524292 1.0"/>
      </material>
    </visual>
    <collision>
      <origin xyz="0.0 0.0 0.0" rpy="0.0 -0.0 0.0"/>
      <geometry>
        <sphere radius="0.043"/>
      </geometry>
    </collision>
    <inertial>
      <origin xyz="0 0 0" rpy="0.0 -0.0 0.0"/>
      <mass value="0.0"/>
      <inertia ixx="0" ixy="0.0" ixz="0.0" iyy="0" iyz="0.0" izz="0"/>
    </inertial>
  </link>
  <link name="link20---bottom-sphere">
    <visual>
      <origin xyz="0 0 0" rpy="0.0 -0.0 0.0"/>
      <geometry>
        <sphere radius="0.043"/>
      </geometry>
      <material name="color-171-128-85-255">
        <color rgba="0.672940731048584 0.504705548286438 0.336470365524292 1.0"/>
      </material>
    </visual>
    <collision>
      <origin xyz="0.0 0.0 0.0" rpy="0.0 -0.0 0.0"/>
      <geometry>
        <sphere radius="0.043"/>
      </geometry>
    </collision>
    <inertial>
      <origin xyz="0 0 0" rpy="0.0 -0.0 0.0"/>
      <mass value="0.0"/>
      <inertia ixx="0" ixy="0.0" ixz="0.0" iyy="0" iyz="0.0" izz="0"/>
    </inertial>
  </link>
  <link name="link21">
    <visual>
      <origin xyz="0.0 0.01 0.0" rpy="0.0 -0.0 0.0"/>
      <geometry>
        <sphere radius="0.038"/>
      </geometry>
      <material name="color-171-128-85-255">
        <color rgba="0.672940731048584 0.504705548286438 0.336470365524292 1.0"/>
      </material>
    </visual>
    <inertial>
      <origin xyz="0.0 0.0 0.0" rpy="0.0 -0.0 0.0"/>
      <mass value="0.0"/>
      <inertia ixx="0.0" ixy="0.0" ixz="0.0" iyy="0.0" iyz="0.0" izz="0.0"/>
    </inertial>
  </link>
  <link name="link22">
    <visual>
      <origin xyz="0.0 0.0 -0.1285" rpy="0.0 -0.0 0.0"/>
      <geometry>
        <cylinder radius="0.033" length="0.257"/>
      </geometry>
      <material name="color-171-128-85-255">
        <color rgba="0.672940731048584 0.504705548286438 0.336470365524292 1.0"/>
      </material>
    </visual>
    <collision>
      <origin xyz="0.0 0.0 -0.12849999964237213" rpy="0.0 -0.0 0.0"/>
      <geometry>
        <cylinder radius="0.033" length="0.257"/>
      </geometry>
    </collision>
    <inertial>
      <origin xyz="0.0 0.0 0.0" rpy="0.0 -0.0 0.0"/>
      <mass value="0.0"/>
      <inertia ixx="0.0" ixy="0.0" ixz="0.0" iyy="0.0" iyz="0.0" izz="0.0"/>
    </inertial>
  </link>
  <link name="link22---top-sphere">
    <visual>
      <origin xyz="0 0 0" rpy="0.0 -0.0 0.0"/>
      <geometry>
        <sphere radius="0.033"/>
      </geometry>
      <material name="color-171-128-85-255">
        <color rgba="0.672940731048584 0.504705548286438 0.336470365524292 1.0"/>
      </material>
    </visual>
    <collision>
      <origin xyz="0.0 0.0 0.0" rpy="0.0 -0.0 0.0"/>
      <geometry>
        <sphere radius="0.033"/>
      </geometry>
    </collision>
    <inertial>
      <origin xyz="0 0 0" rpy="0.0 -0.0 0.0"/>
      <mass value="0.0"/>
      <inertia ixx="0" ixy="0.0" ixz="0.0" iyy="0" iyz="0.0" izz="0"/>
    </inertial>
  </link>
  <link name="link22---bottom-sphere">
    <visual>
      <origin xyz="0 0 0" rpy="0.0 -0.0 0.0"/>
      <geometry>
        <sphere radius="0.033"/>
      </geometry>
      <material name="color-171-128-85-255">
        <color rgba="0.672940731048584 0.504705548286438 0.336470365524292 1.0"/>
      </material>
    </visual>
    <collision>
      <origin xyz="0.0 0.0 0.0" rpy="0.0 -0.0 0.0"/>
      <geometry>
        <sphere radius="0.033"/>
      </geometry>
    </collision>
    <inertial>
      <origin xyz="0 0 0" rpy="0.0 -0.0 0.0"/>
      <mass value="0.0"/>
      <inertia ixx="0" ixy="0.0" ixz="0.0" iyy="0" iyz="0.0" izz="0"/>
    </inertial>
  </link>
  <link name="link23">
    <inertial>
      <origin xyz="0.0 0.0 0.0" rpy="0.0 -0.0 0.0"/>
      <mass value="0.0"/>
      <inertia ixx="0.0" ixy="0.0" ixz="0.0" iyy="0.0" iyz="0.0" izz="0.0"/>
    </inertial>
  </link>
  <link name="link24">
    <visual>
      <origin xyz="0.0 0.0 -0.043" rpy="0.0 -0.0 0.0"/>
      <geometry>
        <sphere radius="0.043"/>
      </geometry>
      <material name="color-171-128-85-255">
        <color rgba="0.672940731048584 0.504705548286438 0.336470365524292 1.0"/>
      </material>
    </visual>
    <collision>
      <origin xyz="0.0 0.0 -0.0430000014603138" rpy="0.0 -0.0 0.0"/>
      <geometry>
        <sphere radius="0.043"/>
      </geometry>
    </collision>
    <inertial>
      <origin xyz="0.0 0.0 0.0" rpy="0.0 -0.0 0.0"/>
      <mass value="0.0"/>
      <inertia ixx="0.0" ixy="0.0" ixz="0.0" iyy="0.0" iyz="0.0" izz="0.0"/>
    </inertial>
  </link>
  <link name="link7">
    <visual>
      <origin xyz="0.0 0.0 0.09000000000000002" rpy="0.0 -0.0 0.0"/>
      <geometry>
        <cylinder radius="0.06" length="0.124"/>
      </geometry>
      <material name="color-171-128-85-255">
        <color rgba="0.672940731048584 0.504705548286438 0.336470365524292 1.0"/>
      </material>
    </visual>
    <collision>
      <origin xyz="0.0 0.0 0.09000000357627869" rpy="0.0 -0.0 0.0"/>
      <geometry>
        <cylinder radius="0.06" length="0.124"/>
      </geometry>
    </collision>
    <inertial>
      <origin xyz="0.0 0.0 0.0" rpy="0.0 -0.0 0.0"/>
      <mass value="0.0"/>
      <inertia ixx="0.0" ixy="0.0" ixz="0.0" iyy="0.0" iyz="0.0" izz="0.0"/>
    </inertial>
  </link>
  <link name="link7---top-sphere">
    <visual>
      <origin xyz="0 0 0" rpy="0.0 -0.0 0.0"/>
      <geometry>
        <sphere radius="0.06"/>
      </geometry>
      <material name="color-171-128-85-255">
        <color rgba="0.672940731048584 0.504705548286438 0.336470365524292 1.0"/>
      </material>
    </visual>
    <collision>
      <origin xyz="0.0 0.0 0.0" rpy="0.0 -0.0 0.0"/>
      <geometry>
        <sphere radius="0.06"/>
      </geometry>
    </collision>
    <inertial>
      <origin xyz="0 0 0" rpy="0.0 -0.0 0.0"/>
      <mass value="0.0"/>
      <inertia ixx="0" ixy="0.0" ixz="0.0" iyy="0" iyz="0.0" izz="0"/>
    </inertial>
  </link>
  <link name="link7---bottom-sphere">
    <visual>
      <origin xyz="0 0 0" rpy="0.0 -0.0 0.0"/>
      <geometry>
        <sphere radius="0.06"/>
      </geometry>
      <material name="color-171-128-85-255">
        <color rgba="0.672940731048584 0.504705548286438 0.336470365524292 1.0"/>
      </material>
    </visual>
    <collision>
      <origin xyz="0.0 0.0 0.0" rpy="0.0 -0.0 0.0"/>
      <geometry>
        <sphere radius="0.06"/>
      </geometry>
    </collision>
    <inertial>
      <origin xyz="0 0 0" rpy="0.0 -0.0 0.0"/>
      <mass value="0.0"/>
      <inertia ixx="0" ixy="0.0" ixz="0.0" iyy="0" iyz="0.0" izz="0"/>
    </inertial>
  </link>
  <link name="link8">
    <inertial>
      <origin xyz="0.0 0.0 0.0" rpy="0.0 -0.0 0.0"/>
      <mass value="0.0"/>
      <inertia ixx="0.0" ixy="0.0" ixz="0.0" iyy="0.0" iyz="0.0" izz="0.0"/>
    </inertial>
  </link>
  <link name="link9">
    <inertial>
      <origin xyz="0.0 0.0 0.0" rpy="0.0 -0.0 0.0"/>
      <mass value="0.0"/>
      <inertia ixx="0.0" ixy="0.0" ixz="0.0" iyy="0.0" iyz="0.0" izz="0.0"/>
    </inertial>
  </link>
  <link name="link10">
    <visual>
      <origin xyz="0.09 0.08 -0.060000000000000005" rpy="1.5707963267948966 -0.0 0.0"/>
      <geometry>
        <mesh filename="package://head_female_male/BaseHeadMeshes_v5_male_cropped_reduced_compressed.obj" scale="0.89 0.89 0.89"/>
      </geometry>
      <material name="color-171-128-85-255">
        <color rgba="0.672940731048584 0.504705548286438 0.336470365524292 1.0"/>
      </material>
    </visual>
    <collision>
      <origin xyz="0.09 0.08 -0.060000000000000005" rpy="1.5707963267948966 -0.0 0.0"/>
      <geometry>
        <mesh filename="package://head_female_male/BaseHeadMeshes_v5_male_cropped_reduced_compressed.obj" scale="0.89 0.89 0.89"/>
      </geometry>
    </collision>
    <inertial>
      <origin xyz="0.0 0.0 0.0" rpy="0.0 -0.0 0.0"/>
      <mass value="0.0"/>
      <inertia ixx="0.0" ixy="0.0" ixz="0.0" iyy="0.0" iyz="0.0" izz="0.0"/>
    </inertial>
  </link>
  <link name="link25">
    <visual>
      <origin xyz="0.0 0.0 0.0" rpy="-0.0 1.5707963267948966 0.0"/>
      <geometry>
        <cylinder radius="0.1205" length="0.049"/>
      </geometry>
      <material name="color-171-128-85-255">
        <color rgba="0.672940731048584 0.504705548286438 0.336470365524292 1.0"/>
      </material>
    </visual>
    <collision>
      <origin xyz="0.0 0.0 0.0" rpy="-0.0 1.5707963267948966 0.0"/>
      <geometry>
        <cylinder radius="0.1205" length="0.049"/>
      </geometry>
    </collision>
    <inertial>
      <origin xyz="0.0 0.0 0.0" rpy="0.0 -0.0 0.0"/>
      <mass value="0.0"/>
      <inertia ixx="0.0" ixy="0.0" ixz="0.0" iyy="0.0" iyz="0.0" izz="0.0"/>
    </inertial>
  </link>
  <link name="link25---top-sphere">
    <visual>
      <origin xyz="0 0 0" rpy="0.0 -0.0 0.0"/>
      <geometry>
        <sphere radius="0.1205"/>
      </geometry>
      <material name="color-171-128-85-255">
        <color rgba="0.672940731048584 0.504705548286438 0.336470365524292 1.0"/>
      </material>
    </visual>
    <collision>
      <origin xyz="0.0 0.0 0.0" rpy="0.0 -0.0 0.0"/>
      <geometry>
        <sphere radius="0.1205"/>
      </geometry>
    </collision>
    <inertial>
      <origin xyz="0 0 0" rpy="0.0 -0.0 0.0"/>
      <mass value="0.0"/>
      <inertia ixx="0" ixy="0.0" ixz="0.0" iyy="0" iyz="0.0" izz="0"/>
    </inertial>
  </link>
  <link name="link25---bottom-sphere">
    <visual>
      <origin xyz="0 0 0" rpy="0.0 -0.0 0.0"/>
      <geometry>
        <sphere radius="0.1205"/>
      </geometry>
      <material name="color-171-128-85-255">
        <color rgba="0.672940731048584 0.504705548286438 0.336470365524292 1.0"/>
      </material>
    </visual>
    <collision>
      <origin xyz="0.0 0.0 0.0" rpy="0.0 -0.0 0.0"/>
      <geometry>
        <sphere radius="0.1205"/>
      </geometry>
    </collision>
    <inertial>
      <origin xyz="0 0 0" rpy="0.0 -0.0 0.0"/>
      <mass value="0.0"/>
      <inertia ixx="0" ixy="0.0" ixz="0.0" iyy="0" iyz="0.0" izz="0"/>
    </inertial>
  </link>
  <link name="link26">
    <inertial>
      <origin xyz="0.0 0.0 0.0" rpy="0.0 -0.0 0.0"/>
      <mass value="0.0"/>
      <inertia ixx="0.0" ixy="0.0" ixz="0.0" iyy="0.0" iyz="0.0" izz="0.0"/>
    </inertial>
  </link>
  <link name="link27">
    <inertial>
      <origin xyz="0.0 0.0 0.0" rpy="0.0 -0.0 0.0"/>
      <mass value="0.0"/>
      <inertia ixx="0.0" ixy="0.0" ixz="0.0" iyy="0.0" iyz="0.0" izz="0.0"/>
    </inertial>
  </link>
  <link name="link28">
    <visual>
      <origin xyz="0.0 0.0 -0.08125" rpy="-0.0 1.5707963267948966 0.0"/>
      <geometry>
        <cylinder radius="0.1335" length="0.094"/>
      </geometry>
      <material name="color-171-128-85-255">
        <color rgba="0.672940731048584 0.504705548286438 0.336470365524292 1.0"/>
      </material>
    </visual>
    <collision>
      <origin xyz="0.0 0.0 -0.08124999701976776" rpy="-0.0 1.5707963267948966 0.0"/>
      <geometry>
        <cylinder radius="0.1335" length="0.094"/>
      </geometry>
    </collision>
    <inertial>
      <origin xyz="0.0 0.0 0.0" rpy="0.0 -0.0 0.0"/>
      <mass value="0.0"/>
      <inertia ixx="0.0" ixy="0.0" ixz="0.0" iyy="0.0" iyz="0.0" izz="0.0"/>
    </inertial>
  </link>
  <link name="link28---top-sphere">
    <visual>
      <origin xyz="0 0 0" rpy="0.0 -0.0 0.0"/>
      <geometry>
        <sphere radius="0.1335"/>
      </geometry>
      <material name="color-171-128-85-255">
        <color rgba="0.672940731048584 0.504705548286438 0.336470365524292 1.0"/>
      </material>
    </visual>
    <collision>
      <origin xyz="0.0 0.0 0.0" rpy="0.0 -0.0 0.0"/>
      <geometry>
        <sphere radius="0.1335"/>
      </geometry>
    </collision>
    <inertial>
      <origin xyz="0 0 0" rpy="0.0 -0.0 0.0"/>
      <mass value="0.0"/>
      <inertia ixx="0" ixy="0.0" ixz="0.0" iyy="0" iyz="0.0" izz="0"/>
    </inertial>
  </link>
  <link name="link28---bottom-sphere">
    <visual>
      <origin xyz="0 0 0" rpy="0.0 -0.0 0.0"/>
      <geometry>
        <sphere radius="0.1335"/>
      </geometry>
      <material name="color-171-128-85-255">
        <color rgba="0.672940731048584 0.504705548286438 0.336470365524292 1.0"/>
      </material>
    </visual>
    <collision>
      <origin xyz="0.0 0.0 0.0" rpy="0.0 -0.0 0.0"/>
      <geometry>
        <sphere radius="0.1335"/>
      </geometry>
    </collision>
    <inertial>
      <origin xyz="0 0 0" rpy="0.0 -0.0 0.0"/>
      <mass value="0.0"/>
      <inertia ixx="0" ixy="0.0" ixz="0.0" iyy="0" iyz="0.0" izz="0"/>
    </inertial>
  </link>
  <link name="link29">
    <inertial>
      <origin xyz="0.0 0.0 0.0" rpy="0.0 -0.0 0.0"/>
      <mass value="0.0"/>
      <inertia ixx="0.0" ixy="0.0" ixz="0.0" iyy="0.0" iyz="0.0" izz="0.0"/>
    </inertial>
  </link>
  <link name="link30">
    <inertial>
      <origin xyz="0.0 0.0 0.0" rpy="0.0 -0.0 0.0"/>
      <mass value="0.0"/>
      <inertia ixx="0.0" ixy="0.0" ixz="0.0" iyy="0.0" iyz="0.0" izz="0.0"/>
    </inertial>
  </link>
  <link name="link31">
    <visual>
      <origin xyz="0.0 0.0 -0.212" rpy="0.0 -0.0 0.0"/>
      <geometry>
        <cylinder radius="0.08" length="0.424"/>
      </geometry>
      <material name="color-171-128-85-255">
        <color rgba="0.672940731048584 0.504705548286438 0.336470365524292 1.0"/>
      </material>
    </visual>
    <collision>
      <origin xyz="0.0 0.0 -0.21199999749660492" rpy="0.0 -0.0 0.0"/>
      <geometry>
        <cylinder radius="0.08" length="0.424"/>
      </geometry>
    </collision>
    <inertial>
      <origin xyz="0.0 0.0 0.0" rpy="0.0 -0.0 0.0"/>
      <mass value="0.0"/>
      <inertia ixx="0.0" ixy="0.0" ixz="0.0" iyy="0.0" iyz="0.0" izz="0.0"/>
    </inertial>
  </link>
  <link name="link31---top-sphere">
    <visual>
      <origin xyz="0 0 0" rpy="0.0 -0.0 0.0"/>
      <geometry>
        <sphere radius="0.08"/>
      </geometry>
      <material name="color-171-128-85-255">
        <color rgba="0.672940731048584 0.504705548286438 0.336470365524292 1.0"/>
      </material>
    </visual>
    <collision>
      <origin xyz="0.0 0.0 0.0" rpy="0.0 -0.0 0.0"/>
      <geometry>
        <sphere radius="0.08"/>
      </geometry>
    </collision>
    <inertial>
      <origin xyz="0 0 0" rpy="0.0 -0.0 0.0"/>
      <mass value="0.0"/>
      <inertia ixx="0" ixy="0.0" ixz="0.0" iyy="0" iyz="0.0" izz="0"/>
    </inertial>
  </link>
  <link name="link31---bottom-sphere">
    <visual>
      <origin xyz="0 0 0" rpy="0.0 -0.0 0.0"/>
      <geometry>
        <sphere radius="0.08"/>
      </geometry>
      <material name="color-171-128-85-255">
        <color rgba="0.672940731048584 0.504705548286438 0.336470365524292 1.0"/>
      </material>
    </visual>
    <collision>
      <origin xyz="0.0 0.0 0.0" rpy="0.0 -0.0 0.0"/>
      <geometry>
        <sphere radius="0.08"/>
      </geometry>
    </collision>
    <inertial>
      <origin xyz="0 0 0" rpy="0.0 -0.0 0.0"/>
      <mass value="0.0"/>
      <inertia ixx="0" ixy="0.0" ixz="0.0" iyy="0" iyz="0.0" izz="0"/>
    </inertial>
  </link>
  <link name="link32">
    <visual>
      <origin xyz="0.0 0.0 -0.2015" rpy="0.0 -0.0 0.0"/>
      <geometry>
        <cylinder radius="0.05" length="0.403"/>
      </geometry>
      <material name="color-171-128-85-255">
        <color rgba="0.672940731048584 0.504705548286438 0.336470365524292 1.0"/>
      </material>
    </visual>
    <collision>
      <origin xyz="0.0 0.0 -0.20149999856948853" rpy="0.0 -0.0 0.0"/>
      <geometry>
        <cylinder radius="0.05" length="0.403"/>
      </geometry>
    </collision>
    <inertial>
      <origin xyz="0.0 0.0 0.0" rpy="0.0 -0.0 0.0"/>
      <mass value="0.0"/>
      <inertia ixx="0.0" ixy="0.0" ixz="0.0" iyy="0.0" iyz="0.0" izz="0.0"/>
    </inertial>
  </link>
  <link name="link32---top-sphere">
    <visual>
      <origin xyz="0 0 0" rpy="0.0 -0.0 0.0"/>
      <geometry>
        <sphere radius="0.05"/>
      </geometry>
      <material name="color-171-128-85-255">
        <color rgba="0.672940731048584 0.504705548286438 0.336470365524292 1.0"/>
      </material>
    </visual>
    <collision>
      <origin xyz="0.0 0.0 0.0" rpy="0.0 -0.0 0.0"/>
      <geometry>
        <sphere radius="0.05"/>
      </geometry>
    </collision>
    <inertial>
      <origin xyz="0 0 0" rpy="0.0 -0.0 0.0"/>
      <mass value="0.0"/>
      <inertia ixx="0" ixy="0.0" ixz="0.0" iyy="0" iyz="0.0" izz="0"/>
    </inertial>
  </link>
  <link name="link32---bottom-sphere">
    <visual>
      <origin xyz="0 0 0" rpy="0.0 -0.0 0.0"/>
      <geometry>
        <sphere radius="0.05"/>
      </geometry>
      <material name="color-171-128-85-255">
        <color rgba="0.672940731048584 0.504705548286438 0.336470365524292 1.0"/>
      </material>
    </visual>
    <collision>
      <origin xyz="0.0 0.0 0.0" rpy="0.0 -0.0 0.0"/>
      <geometry>
        <sphere radius="0.05"/>
      </geometry>
    </collision>
    <inertial>
      <origin xyz="0 0 0" rpy="0.0 -0.0 0.0"/>
      <mass value="0.0"/>
      <inertia ixx="0" ixy="0.0" ixz="0.0" iyy="0" iyz="0.0" izz="0"/>
    </inertial>
  </link>
  <link name="link33">
    <inertial>
      <origin xyz="0.0 0.0 0.0" rpy="0.0 -0.0 0.0"/>
      <mass value="0.0"/>
      <inertia ixx="0.0" ixy="0.0" ixz="0.0" iyy="0.0" iyz="0.0" izz="0.0"/>
    </inertial>
  </link>
  <link name="link34">
    <inertial>
      <origin xyz="0.0 0.0 0.0" rpy="0.0 -0.0 0.0"/>
      <mass value="0.0"/>
      <inertia ixx="0.0" ixy="0.0" ixz="0.0" iyy="0.0" iyz="0.0" izz="0.0"/>
    </inertial>
  </link>
  <link name="link35">
    <visual>
      <origin xyz="0.0 -0.1 -0.025" rpy="1.5707963267948966 -0.0 0.0"/>
      <geometry>
        <cylinder radius="0.05" length="0.215"/>
      </geometry>
      <material name="color-171-128-85-255">
        <color rgba="0.672940731048584 0.504705548286438 0.336470365524292 1.0"/>
      </material>
    </visual>
    <collision>
      <origin xyz="0.0 -0.10000000149011612 -0.02500000037252903" rpy="1.5707963267948966 -0.0 0.0"/>
      <geometry>
        <cylinder radius="0.05" length="0.215"/>
      </geometry>
    </collision>
    <inertial>
      <origin xyz="0.0 0.0 0.0" rpy="0.0 -0.0 0.0"/>
      <mass value="0.0"/>
      <inertia ixx="0.0" ixy="0.0" ixz="0.0" iyy="0.0" iyz="0.0" izz="0.0"/>
    </inertial>
  </link>
  <link name="link35---top-sphere">
    <visual>
      <origin xyz="0 0 0" rpy="0.0 -0.0 0.0"/>
      <geometry>
        <sphere radius="0.05"/>
      </geometry>
      <material name="color-171-128-85-255">
        <color rgba="0.672940731048584 0.504705548286438 0.336470365524292 1.0"/>
      </material>
    </visual>
    <collision>
      <origin xyz="0.0 0.0 0.0" rpy="0.0 -0.0 0.0"/>
      <geometry>
        <sphere radius="0.05"/>
      </geometry>
    </collision>
    <inertial>
      <origin xyz="0 0 0" rpy="0.0 -0.0 0.0"/>
      <mass value="0.0"/>
      <inertia ixx="0" ixy="0.0" ixz="0.0" iyy="0" iyz="0.0" izz="0"/>
    </inertial>
  </link>
  <link name="link35---bottom-sphere">
    <visual>
      <origin xyz="0 0 0" rpy="0.0 -0.0 0.0"/>
      <geometry>
        <sphere radius="0.05"/>
      </geometry>
      <material name="color-171-128-85-255">
        <color rgba="0.672940731048584 0.504705548286438 0.336470365524292 1.0"/>
      </material>
    </visual>
    <collision>
      <origin xyz="0.0 0.0 0.0" rpy="0.0 -0.0 0.0"/>
      <geometry>
        <sphere radius="0.05"/>
      </geometry>
    </collision>
    <inertial>
      <origin xyz="0 0 0" rpy="0.0 -0.0 0.0"/>
      <mass value="0.0"/>
      <inertia ixx="0" ixy="0.0" ixz="0.0" iyy="0" iyz="0.0" izz="0"/>
    </inertial>
  </link>
  <link name="link36">
    <inertial>
      <origin xyz="0.0 0.0 0.0" rpy="0.0 -0.0 0.0"/>
      <mass value="0.0"/>
      <inertia ixx="0.0" ixy="0.0" ixz="0.0" iyy="0.0" iyz="0.0" izz="0.0"/>
    </inertial>
  </link>
  <link name="link37">
    <inertial>
      <origin xyz="0.0 0.0 0.0" rpy="0.0 -0.0 0.0"/>
      <mass value="0.0"/>
      <inertia ixx="0.0" ixy="0.0" ixz="0.0" iyy="0.0" iyz="0.0" izz="0.0"/>
    </inertial>
  </link>
  <link name="link38">
    <visual>
      <origin xyz="0.0 0.0 -0.212" rpy="0.0 -0.0 0.0"/>
      <geometry>
        <cylinder radius="0.08" length="0.424"/>
      </geometry>
      <material name="color-171-128-85-255">
        <color rgba="0.672940731048584 0.504705548286438 0.336470365524292 1.0"/>
      </material>
    </visual>
    <collision>
      <origin xyz="0.0 0.0 -0.21199999749660492" rpy="0.0 -0.0 0.0"/>
      <geometry>
        <cylinder radius="0.08" length="0.424"/>
      </geometry>
    </collision>
    <inertial>
      <origin xyz="0.0 0.0 0.0" rpy="0.0 -0.0 0.0"/>
      <mass value="0.0"/>
      <inertia ixx="0.0" ixy="0.0" ixz="0.0" iyy="0.0" iyz="0.0" izz="0.0"/>
    </inertial>
  </link>
  <link name="link38---top-sphere">
    <visual>
      <origin xyz="0 0 0" rpy="0.0 -0.0 0.0"/>
      <geometry>
        <sphere radius="0.08"/>
      </geometry>
      <material name="color-171-128-85-255">
        <color rgba="0.672940731048584 0.504705548286438 0.336470365524292 1.0"/>
      </material>
    </visual>
    <collision>
      <origin xyz="0.0 0.0 0.0" rpy="0.0 -0.0 0.0"/>
      <geometry>
        <sphere radius="0.08"/>
      </geometry>
    </collision>
    <inertial>
      <origin xyz="0 0 0" rpy="0.0 -0.0 0.0"/>
      <mass value="0.0"/>
      <inertia ixx="0" ixy="0.0" ixz="0.0" iyy="0" iyz="0.0" izz="0"/>
    </inertial>
  </link>
  <link name="link38---bottom-sphere">
    <visual>
      <origin xyz="0 0 0" rpy="0.0 -0.0 0.0"/>
      <geometry>
        <sphere radius="0.08"/>
      </geometry>
      <material name="color-171-128-85-255">
        <color rgba="0.672940731048584 0.504705548286438 0.336470365524292 1.0"/>
      </material>
    </visual>
    <collision>
      <origin xyz="0.0 0.0 0.0" rpy="0.0 -0.0 0.0"/>
      <geometry>
        <sphere radius="0.08"/>
      </geometry>
    </collision>
    <inertial>
      <origin xyz="0 0 0" rpy="0.0 -0.0 0.0"/>
      <mass value="0.0"/>
      <inertia ixx="0" ixy="0.0" ixz="0.0" iyy="0" iyz="0.0" izz="0"/>
    </inertial>
  </link>
  <link name="link39">
    <visual>
      <origin xyz="0.0 0.0 -0.2015" rpy="0.0 -0.0 0.0"/>
      <geometry>
        <cylinder radius="0.05" length="0.403"/>
      </geometry>
      <material name="color-171-128-85-255">
        <color rgba="0.672940731048584 0.504705548286438 0.336470365524292 1.0"/>
      </material>
    </visual>
    <collision>
      <origin xyz="0.0 0.0 -0.20149999856948853" rpy="0.0 -0.0 0.0"/>
      <geometry>
        <cylinder radius="0.05" length="0.403"/>
      </geometry>
    </collision>
    <inertial>
      <origin xyz="0.0 0.0 0.0" rpy="0.0 -0.0 0.0"/>
      <mass value="0.0"/>
      <inertia ixx="0.0" ixy="0.0" ixz="0.0" iyy="0.0" iyz="0.0" izz="0.0"/>
    </inertial>
  </link>
  <link name="link39---top-sphere">
    <visual>
      <origin xyz="0 0 0" rpy="0.0 -0.0 0.0"/>
      <geometry>
        <sphere radius="0.05"/>
      </geometry>
      <material name="color-171-128-85-255">
        <color rgba="0.672940731048584 0.504705548286438 0.336470365524292 1.0"/>
      </material>
    </visual>
    <collision>
      <origin xyz="0.0 0.0 0.0" rpy="0.0 -0.0 0.0"/>
      <geometry>
        <sphere radius="0.05"/>
      </geometry>
    </collision>
    <inertial>
      <origin xyz="0 0 0" rpy="0.0 -0.0 0.0"/>
      <mass value="0.0"/>
      <inertia ixx="0" ixy="0.0" ixz="0.0" iyy="0" iyz="0.0" izz="0"/>
    </inertial>
  </link>
  <link name="link39---bottom-sphere">
    <visual>
      <origin xyz="0 0 0" rpy="0.0 -0.0 0.0"/>
      <geometry>
        <sphere radius="0.05"/>
      </geometry>
      <material name="color-171-128-85-255">
        <color rgba="0.672940731048584 0.504705548286438 0.336470365524292 1.0"/>
      </material>
    </visual>
    <collision>
      <origin xyz="0.0 0.0 0.0" rpy="0.0 -0.0 0.0"/>
      <geometry>
        <sphere radius="0.05"/>
      </geometry>
    </collision>
    <inertial>
      <origin xyz="0 0 0" rpy="0.0 -0.0 0.0"/>
      <mass value="0.0"/>
      <inertia ixx="0" ixy="0.0" ixz="0.0" iyy="0" iyz="0.0" izz="0"/>
    </inertial>
  </link>
  <link name="link40">
    <inertial>
      <origin xyz="0.0 0.0 0.0" rpy="0.0 -0.0 0.0"/>
      <mass value="0.0"/>
      <inertia ixx="0.0" ixy="0.0" ixz="0.0" iyy="0.0" iyz="0.0" izz="0.0"/>
    </inertial>
  </link>
  <link name="link41">
    <inertial>
      <origin xyz="0.0 0.0 0.0" rpy="0.0 -0.0 0.0"/>
      <mass value="0.0"/>
      <inertia ixx="0.0" ixy="0.0" ixz="0.0" iyy="0.0" iyz="0.0" izz="0.0"/>
    </inertial>
  </link>
  <link name="link42">
    <visual>
      <origin xyz="0.0 -0.1 -0.025" rpy="1.5707963267948966 -0.0 0.0"/>
      <geometry>
        <cylinder radius="0.05" length="0.215"/>
      </geometry>
      <material name="color-171-128-85-255">
        <color rgba="0.672940731048584 0.504705548286438 0.336470365524292 1.0"/>
      </material>
    </visual>
    <collision>
      <origin xyz="0.0 -0.10000000149011612 -0.02500000037252903" rpy="1.5707963267948966 -0.0 0.0"/>
      <geometry>
        <cylinder radius="0.05" length="0.215"/>
      </geometry>
    </collision>
    <inertial>
      <origin xyz="0.0 0.0 0.0" rpy="0.0 -0.0 0.0"/>
      <mass value="0.0"/>
      <inertia ixx="0.0" ixy="0.0" ixz="0.0" iyy="0.0" iyz="0.0" izz="0.0"/>
    </inertial>
  </link>
  <link name="link42---top-sphere">
    <visual>
      <origin xyz="0 0 0" rpy="0.0 -0.0 0.0"/>
      <geometry>
        <sphere radius="0.05"/>
      </geometry>
      <material name="color-171-128-85-255">
        <color rgba="0.672940731048584 0.504705548286438 0.336470365524292 1.0"/>
      </material>
    </visual>
    <collision>
      <origin xyz="0.0 0.0 0.0" rpy="0.0 -0.0 0.0"/>
      <geometry>
        <sphere radius="0.05"/>
      </geometry>
    </collision>
    <inertial>
      <origin xyz="0 0 0" rpy="0.0 -0.0 0.0"/>
      <mass value="0.0"/>
      <inertia ixx="0" ixy="0.0" ixz="0.0" iyy="0" iyz="0.0" izz="0"/>
    </inertial>
  </link>
  <link name="link42---bottom-sphere">
    <visual>
      <origin xyz="0 0 0" rpy="0.0 -0.0 0.0"/>
      <geometry>
        <sphere radius="0.05"/>
      </geometry>
      <material name="color-171-128-85-255">
        <color rgba="0.672940731048584 0.504705548286438 0.336470365524292 1.0"/>
      </material>
    </visual>
    <collision>
      <origin xyz="0.0 0.0 0.0" rpy="0.0 -0.0 0.0"/>
      <geometry>
        <sphere radius="0.05"/>
      </geometry>
    </collision>
    <inertial>
      <origin xyz="0 0 0" rpy="0.0 -0.0 0.0"/>
      <mass value="0.0"/>
      <inertia ixx="0" ixy="0.0" ixz="0.0" iyy="0" iyz="0.0" izz="0"/>
    </inertial>
  </link>
  <joint name="base_link---top-sphere-fixed-joint" type="fixed">
    <parent link="base_link"/>
    <child link="base_link---top-sphere"/>
    <origin xyz="0.06350000202655792 0.0 0.0" rpy="0.0 -1.5707963267948966 0.0"/>
  </joint>
  <joint name="base_link---bottom-sphere-fixed-joint" type="fixed">
    <parent link="base_link"/>
    <child link="base_link---bottom-sphere"/>
    <origin xyz="-0.06350000202655792 0.0 0.0" rpy="0.0 -1.5707963267948966 0.0"/>
  </joint>
  <joint name="link3---top-sphere-fixed-joint" type="fixed">
    <parent link="link3"/>
    <child link="link3---top-sphere"/>
    <origin xyz="-0.03238749876618385 0.0 0.0" rpy="0.0 -1.5707963267948966 0.0"/>
  </joint>
  <joint name="link3---bottom-sphere-fixed-joint" type="fixed">
    <parent link="link3"/>
    <child link="link3---bottom-sphere"/>
    <origin xyz="-0.1383875012397766 0.0 0.0" rpy="0.0 -1.5707963267948966 0.0"/>
  </joint>
  <joint name="link13---top-sphere-fixed-joint" type="fixed">
    <parent link="link13"/>
    <child link="link13---top-sphere"/>
    <origin xyz="0.0 0.0 -0.11800000816583633" rpy="0.0 -0.0 0.0"/>
  </joint>
  <joint name="link13---bottom-sphere-fixed-joint" type="fixed">
    <parent link="link13"/>
    <child link="link13---bottom-sphere"/>
    <origin xyz="0.0 0.0 -0.16100001335144043" rpy="0.0 -0.0 0.0"/>
  </joint>
  <joint name="link15---top-sphere-fixed-joint" type="fixed">
    <parent link="link15"/>
    <child link="link15---top-sphere"/>
    <origin xyz="0.0 0.0 -0.1120000034570694" rpy="0.0 -0.0 0.0"/>
  </joint>
  <joint name="link15---bottom-sphere-fixed-joint" type="fixed">
    <parent link="link15"/>
    <child link="link15---bottom-sphere"/>
    <origin xyz="0.0 0.0 -0.14499999582767487" rpy="0.0 -0.0 0.0"/>
  </joint>
  <joint name="link6---top-sphere-fixed-joint" type="fixed">
    <parent link="link6"/>
    <child link="link6---top-sphere"/>
    <origin xyz="0.1383875012397766 0.0 0.0" rpy="0.0 -1.5707963267948966 0.0"/>
  </joint>
  <joint name="link6---bottom-sphere-fixed-joint" type="fixed">
    <parent link="link6"/>
    <child link="link6---bottom-sphere"/>
    <origin xyz="0.03238749876618385 0.0 0.0" rpy="0.0 -1.5707963267948966 0.0"/>
  </joint>
  <joint name="link20---top-sphere-fixed-joint" type="fixed">
    <parent link="link20"/>
    <child link="link20---top-sphere"/>
    <origin xyz="0.0 0.0 -0.11800000816583633" rpy="0.0 -0.0 0.0"/>
  </joint>
  <joint name="link20---bottom-sphere-fixed-joint" type="fixed">
    <parent link="link20"/>
    <child link="link20---bottom-sphere"/>
    <origin xyz="0.0 0.0 -0.16100001335144043" rpy="0.0 -0.0 0.0"/>
  </joint>
  <joint name="link22---top-sphere-fixed-joint" type="fixed">
    <parent link="link22"/>
    <child link="link22---top-sphere"/>
    <origin xyz="0.0 0.0 -0.1120000034570694" rpy="0.0 -0.0 0.0"/>
  </joint>
  <joint name="link22---bottom-sphere-fixed-joint" type="fixed">
    <parent link="link22"/>
    <child link="link22---bottom-sphere"/>
    <origin xyz="0.0 0.0 -0.14499999582767487" rpy="0.0 -0.0 0.0"/>
  </joint>
  <joint name="link7---top-sphere-fixed-joint" type="fixed">
    <parent link="link7"/>
    <child link="link7---top-sphere"/>
    <origin xyz="0.0 0.0 0.12000000476837158" rpy="0.0 -0.0 0.0"/>
  </joint>
  <joint name="link7---bottom-sphere-fixed-joint" type="fixed">
    <parent link="link7"/>
    <child link="link7---bottom-sphere"/>
    <origin xyz="0.0 0.0 0.06000000238418579" rpy="0.0 -0.0 0.0"/>
  </joint>
  <joint name="link25---top-sphere-fixed-joint" type="fixed">
    <parent link="link25"/>
    <child link="link25---top-sphere"/>
    <origin xyz="0.06024999916553497 0.0 0.0" rpy="0.0 -1.5707963267948966 0.0"/>
  </joint>
  <joint name="link25---bottom-sphere-fixed-joint" type="fixed">
    <parent link="link25"/>
    <child link="link25---bottom-sphere"/>
    <origin xyz="-0.06024999916553497 0.0 0.0" rpy="0.0 -1.5707963267948966 0.0"/>
  </joint>
  <joint name="link28---top-sphere-fixed-joint" type="fixed">
    <parent link="link28"/>
    <child link="link28---top-sphere"/>
    <origin xyz="0.06674999743700027 0.0 -0.08124999701976776" rpy="0.0 -1.5707963267948966 0.0"/>
  </joint>
  <joint name="link28---bottom-sphere-fixed-joint" type="fixed">
    <parent link="link28"/>
    <child link="link28---bottom-sphere"/>
    <origin xyz="-0.06674999743700027 0.0 -0.08124999701976776" rpy="0.0 -1.5707963267948966 0.0"/>
  </joint>
  <joint name="link31---top-sphere-fixed-joint" type="fixed">
    <parent link="link31"/>
    <child link="link31---top-sphere"/>
    <origin xyz="0.0 0.0 -0.171999990940094" rpy="0.0 -0.0 0.0"/>
  </joint>
  <joint name="link31---bottom-sphere-fixed-joint" type="fixed">
    <parent link="link31"/>
    <child link="link31---bottom-sphere"/>
    <origin xyz="0.0 0.0 -0.25200000405311584" rpy="0.0 -0.0 0.0"/>
  </joint>
  <joint name="link32---top-sphere-fixed-joint" type="fixed">
    <parent link="link32"/>
    <child link="link32---top-sphere"/>
    <origin xyz="0.0 0.0 -0.17649999260902405" rpy="0.0 -0.0 0.0"/>
  </joint>
  <joint name="link32---bottom-sphere-fixed-joint" type="fixed">
    <parent link="link32"/>
    <child link="link32---bottom-sphere"/>
    <origin xyz="0.0 0.0 -0.226500004529953" rpy="0.0 -0.0 0.0"/>
  </joint>
  <joint name="link35---top-sphere-fixed-joint" type="fixed">
    <parent link="link35"/>
    <child link="link35---top-sphere"/>
    <origin xyz="0.0 -0.125 -0.02500000037252903" rpy="-1.5707963267948966 0.0 0.0"/>
  </joint>
  <joint name="link35---bottom-sphere-fixed-joint" type="fixed">
    <parent link="link35"/>
    <child link="link35---bottom-sphere"/>
    <origin xyz="0.0 -0.07500000298023224 -0.02500000037252903" rpy="-1.5707963267948966 0.0 0.0"/>
  </joint>
  <joint name="link38---top-sphere-fixed-joint" type="fixed">
    <parent link="link38"/>
    <child link="link38---top-sphere"/>
    <origin xyz="0.0 0.0 -0.171999990940094" rpy="0.0 -0.0 0.0"/>
  </joint>
  <joint name="link38---bottom-sphere-fixed-joint" type="fixed">
    <parent link="link38"/>
    <child link="link38---bottom-sphere"/>
    <origin xyz="0.0 0.0 -0.25200000405311584" rpy="0.0 -0.0 0.0"/>
  </joint>
  <joint name="link39---top-sphere-fixed-joint" type="fixed">
    <parent link="link39"/>
    <child link="link39---top-sphere"/>
    <origin xyz="0.0 0.0 -0.17649999260902405" rpy="0.0 -0.0 0.0"/>
  </joint>
  <joint name="link39---bottom-sphere-fixed-joint" type="fixed">
    <parent link="link39"/>
    <child link="link39---bottom-sphere"/>
    <origin xyz="0.0 0.0 -0.226500004529953" rpy="0.0 -0.0 0.0"/>
  </joint>
  <joint name="link42---top-sphere-fixed-joint" type="fixed">
    <parent link="link42"/>
    <child link="link42---top-sphere"/>
    <origin xyz="0.0 -0.125 -0.02500000037252903" rpy="-1.5707963267948966 0.0 0.0"/>
  </joint>
  <joint name="link42---bottom-sphere-fixed-joint" type="fixed">
    <parent link="link42"/>
    <child link="link42---bottom-sphere"/>
    <origin xyz="0.0 -0.07500000298023224 -0.02500000037252903" rpy="-1.5707963267948966 0.0 0.0"/>
  </joint>
  <joint name="joint1" type="revolute">
    <parent link="base_link"/>
    <child link="link1"/>
    <origin xyz="0.0 0.0 0.07074999809265137" rpy="0.0 -0.0 0.0"/>
    <axis xyz="1.0 0.0 0.0"/>
    <limit effort="0.0" velocity="0.0" lower="-0.17453292519943295" upper="0.17453292519943295"/>
  </joint>
  <joint name="joint2" type="revolute">
    <parent link="link1"/>
    <child link="link2"/>
    <origin xyz="0.0 0.0 0.07074999809265137" rpy="0.0 -0.0 0.0"/>
    <axis xyz="0.0 1.0 0.0"/>
    <limit effort="0.0" velocity="0.0" lower="-0.17453292519943295" upper="0.5235987755982988"/>
  </joint>
  <joint name="joint3" type="revolute">
    <parent link="link2"/>
    <child link="link3"/>
    <origin xyz="0.0 0.0 0.0" rpy="0.0 -0.0 0.0"/>
    <axis xyz="0.0 0.0 1.0"/>
    <limit effort="0.0" velocity="0.0" lower="-0.6108652381980153" upper="0.6108652381980153"/>
  </joint>
  <joint name="joint11" type="revolute">
    <parent link="link3"/>
    <child link="link11"/>
    <origin xyz="-0.17900000512599945 0.0 0.0" rpy="0.0 -0.0 0.0"/>
    <axis xyz="0.0 1.0 0.0"/>
    <limit effort="0.0" velocity="0.0" lower="0.08726646259971647" upper="3.4557519189487724"/>
  </joint>
  <joint name="joint12" type="revolute">
    <parent link="link11"/>
    <child link="link12"/>
    <origin xyz="0.0 0.0 0.0" rpy="0.0 -0.0 0.0"/>
    <axis xyz="1.0 0.0 0.0"/>
    <limit effort="0.0" velocity="0.0" lower="-3.2812189937493397" upper="1.064650843716541"/>
  </joint>
  <joint name="joint13" type="revolute">
    <parent link="link12"/>
    <child link="link13"/>
    <origin xyz="0.0 0.0 0.0" rpy="0.0 -0.0 0.0"/>
    <axis xyz="0.0 0.0 1.0"/>
    <limit effort="0.0" velocity="0.0" lower="-1.5707963267948966" upper="1.5707963267948966"/>
  </joint>
  <joint name="joint14" type="revolute">
    <parent link="link13"/>
    <child link="link14"/>
    <origin xyz="0.0 0.0 -0.27900001406669617" rpy="0.0 -0.0 0.0"/>
    <axis xyz="1.0 0.0 0.0"/>
    <limit effort="0.0" velocity="0.0" lower="-2.234021442552742" upper="0.0"/>
  </joint>
  <joint name="joint15" type="revolute">
    <parent link="link14"/>
    <child link="link15"/>
    <origin xyz="0.0 0.0 0.0" rpy="0.0 -0.0 0.0"/>
    <axis xyz="0.0 0.0 1.0"/>
    <limit effort="0.0" velocity="0.0" lower="-1.5707963267948966" upper="1.5707963267948966"/>
  </joint>
  <joint name="joint16" type="revolute">
    <parent link="link15"/>
    <child link="link16"/>
    <origin xyz="0.0 0.0 -0.28999999165534973" rpy="0.0 -0.0 0.0"/>
    <axis xyz="1.0 0.0 0.0"/>
    <limit effort="0.0" velocity="0.0" lower="-1.413716694115407" upper="1.5707963267948966"/>
  </joint>
  <joint name="joint17" type="revolute">
    <parent link="link16"/>
    <child link="link17"/>
    <origin xyz="0.0 0.0 0.0" rpy="0.0 -0.0 0.0"/>
    <axis xyz="0.0 1.0 0.0"/>
    <limit effort="0.0" velocity="0.0" lower="-0.47123889803846897" upper="0.8203047484373349"/>
  </joint>
  <joint name="joint4" type="revolute">
    <parent link="base_link"/>
    <child link="link4"/>
    <origin xyz="0.0 0.0 0.07074999809265137" rpy="0.0 -0.0 0.0"/>
    <axis xyz="1.0 0.0 0.0"/>
    <limit effort="0.0" velocity="0.0" lower="-0.17453292519943295" upper="0.17453292519943295"/>
  </joint>
  <joint name="joint5" type="revolute">
    <parent link="link4"/>
    <child link="link5"/>
    <origin xyz="0.0 0.0 0.07074999809265137" rpy="0.0 -0.0 0.0"/>
    <axis xyz="0.0 1.0 0.0"/>
    <limit effort="0.0" velocity="0.0" lower="-0.5235987755982988" upper="0.17453292519943295"/>
  </joint>
  <joint name="joint6" type="revolute">
    <parent link="link5"/>
    <child link="link6"/>
    <origin xyz="0.0 0.0 0.0" rpy="0.0 -0.0 0.0"/>
    <axis xyz="0.0 0.0 1.0"/>
    <limit effort="0.0" velocity="0.0" lower="-0.6108652381980153" upper="0.6108652381980153"/>
  </joint>
  <joint name="joint18" type="revolute">
    <parent link="link6"/>
    <child link="link18"/>
    <origin xyz="0.17900000512599945 0.0 0.0" rpy="0.0 -0.0 0.0"/>
    <axis xyz="0.0 1.0 0.0"/>
    <limit effort="0.0" velocity="0.0" lower="-3.4557519189487724" upper="-0.08726646259971647"/>
  </joint>
  <joint name="joint19" type="revolute">
    <parent link="link18"/>
    <child link="link19"/>
    <origin xyz="0.0 0.0 0.0" rpy="0.0 -0.0 0.0"/>
    <axis xyz="1.0 0.0 0.0"/>
    <limit effort="0.0" velocity="0.0" lower="-3.2812189937493397" upper="1.064650843716541"/>
  </joint>
  <joint name="joint20" type="revolute">
    <parent link="link19"/>
    <child link="link20"/>
    <origin xyz="0.0 0.0 0.0" rpy="0.0 -0.0 0.0"/>
    <axis xyz="0.0 0.0 1.0"/>
    <limit effort="0.0" velocity="0.0" lower="-1.5707963267948966" upper="1.5707963267948966"/>
  </joint>
  <joint name="joint21" type="revolute">
    <parent link="link20"/>
    <child link="link21"/>
    <origin xyz="0.0 0.0 -0.27900001406669617" rpy="0.0 -0.0 0.0"/>
    <axis xyz="1.0 0.0 0.0"/>
    <limit effort="0.0" velocity="0.0" lower="-2.234021442552742" upper="0.0"/>
  </joint>
  <joint name="joint22" type="revolute">
    <parent link="link21"/>
    <child link="link22"/>
    <origin xyz="0.0 0.0 0.0" rpy="0.0 -0.0 0.0"/>
    <axis xyz="0.0 0.0 1.0"/>
    <limit effort="0.0" velocity="0.0" lower="-1.5707963267948966" upper="1.5707963267948966"/>
  </joint>
  <joint name="joint23" type="revolute">
    <parent link="link22"/>
    <child link="link23"/>
    <origin xyz="0.0 0.0 -0.28999999165534973" rpy="0.0 -0.0 0.0"/>
    <axis xyz="1.0 0.0 0.0"/>
    <limit effort="0.0" velocity="0.0" lower="-1.413716694115407" upper="1.5707963267948966"/>
  </joint>
  <joint name="joint24" type="revolute">
    <parent link="link23"/>
    <child link="link24"/>
    <origin xyz="0.0 0.0 0.0" rpy="0.0 -0.0 0.0"/>
    <axis xyz="0.0 1.0 0.0"/>
    <limit effort="0.0" velocity="0.0" lower="-0.8203047484373349" upper="0.47123889803846897"/>
  </joint>
  <joint name="joint7" type="revolute">
    <parent link="base_link"/>
    <child link="link7"/>
    <origin xyz="0.0 0.0 0.15150000154972076" rpy="0.0 -0.0 0.0"/>
    <axis xyz="1.0 0.0 0.0"/>
    <limit effort="0.0" velocity="0.0" lower="-0.17453292519943295" upper="0.3490658503988659"/>
  </joint>
  <joint name="joint8" type="revolute">
    <parent link="link7"/>
    <child link="link8"/>
    <origin xyz="0.0 0.0 0.13699999451637268" rpy="0.0 -0.0 0.0"/>
    <axis xyz="1.0 0.0 0.0"/>
    <limit effort="0.0" velocity="0.0" lower="-0.8726646259971648" upper="0.8726646259971648"/>
  </joint>
  <joint name="joint9" type="revolute">
    <parent link="link8"/>
    <child link="link9"/>
    <origin xyz="0.0 0.0 0.0" rpy="0.0 -0.0 0.0"/>
    <axis xyz="0.0 1.0 0.0"/>
    <limit effort="0.0" velocity="0.0" lower="-0.5934119456780721" upper="0.5934119456780721"/>
  </joint>
  <joint name="joint10" type="revolute">
    <parent link="link9"/>
    <child link="link10"/>
    <origin xyz="0.0 0.0 0.0" rpy="0.0 -0.0 0.0"/>
    <axis xyz="0.0 0.0 1.0"/>
    <limit effort="0.0" velocity="0.0" lower="-1.2217304763960306" upper="1.2217304763960306"/>
  </joint>
  <joint name="joint25" type="fixed">
    <parent link="base_link"/>
    <child link="link25"/>
    <origin xyz="0.0 0.0 -0.15600000321865082" rpy="0.0 -0.0 0.0"/>
  </joint>
  <joint name="joint26" type="revolute">
    <parent link="link25"/>
    <child link="link26"/>
    <origin xyz="0.0 0.0 -0.08124999701976776" rpy="0.0 -0.0 0.0"/>
    <axis xyz="1.0 0.0 0.0"/>
    <limit effort="0.0" velocity="0.0" lower="-1.3089969389957472" upper="0.5235987755982988"/>
  </joint>
  <joint name="joint27" type="revolute">
    <parent link="link26"/>
    <child link="link27"/>
    <origin xyz="0.0 0.0 0.0" rpy="0.0 -0.0 0.0"/>
    <axis xyz="0.0 1.0 0.0"/>
    <limit effort="0.0" velocity="0.0" lower="-0.5235987755982988" upper="0.5235987755982988"/>
  </joint>
  <joint name="joint28" type="revolute">
    <parent link="link27"/>
    <child link="link28"/>
    <origin xyz="0.0 0.0 0.0" rpy="0.0 -0.0 0.0"/>
    <axis xyz="0.0 0.0 1.0"/>
    <limit effort="0.0" velocity="0.0" lower="-0.5235987755982988" upper="0.5235987755982988"/>
  </joint>
  <joint name="joint29" type="revolute">
    <parent link="link28"/>
    <child link="link29"/>
    <origin xyz="-0.08900000154972076 0.0 -0.08124999701976776" rpy="0.0 -0.0 0.0"/>
    <axis xyz="1.0 0.0 0.0"/>
    <limit effort="0.0" velocity="0.0" lower="-2.2165681500327987" upper="0.5235987755982988"/>
  </joint>
  <joint name="joint30" type="revolute">
    <parent link="link29"/>
    <child link="link30"/>
    <origin xyz="0.0 0.0 0.0" rpy="0.0 -0.0 0.0"/>
    <axis xyz="0.0 1.0 0.0"/>
    <limit effort="0.0" velocity="0.0" lower="-0.6981317007977318" upper="0.7853981633974483"/>
  </joint>
  <joint name="joint31" type="revolute">
    <parent link="link30"/>
    <child link="link31"/>
    <origin xyz="0.0 0.0 0.0" rpy="0.0 -0.0 0.0"/>
    <axis xyz="0.0 0.0 1.0"/>
    <limit effort="0.0" velocity="0.0" lower="-0.7853981633974483" upper="0.6981317007977318"/>
  </joint>
  <joint name="joint32" type="revolute">
    <parent link="link31"/>
    <child link="link32"/>
    <origin xyz="0.0 0.0 -0.42399999499320984" rpy="0.0 -0.0 0.0"/>
    <axis xyz="1.0 0.0 0.0"/>
    <limit effort="0.0" velocity="0.0" lower="0.0" upper="2.2689280275926285"/>
  </joint>
  <joint name="joint33" type="revolute">
    <parent link="link32"/>
    <child link="link33"/>
    <origin xyz="0.0 0.0 -0.42800000309944153" rpy="0.0 -0.0 0.0"/>
    <axis xyz="1.0 0.0 0.0"/>
    <limit effort="0.0" velocity="0.0" lower="-0.6108652381980153" upper="0.6632251157578453"/>
  </joint>
  <joint name="joint34" type="revolute">
    <parent link="link33"/>
    <child link="link34"/>
    <origin xyz="0.0 0.0 0.0" rpy="0.0 -0.0 0.0"/>
    <axis xyz="0.0 1.0 0.0"/>
    <limit effort="0.0" velocity="0.0" lower="-0.4014257279586958" upper="0.4188790204786391"/>
  </joint>
  <joint name="joint35" type="revolute">
    <parent link="link34"/>
    <child link="link35"/>
    <origin xyz="0.0 0.0 0.0" rpy="0.0 -0.0 0.0"/>
    <axis xyz="0.0 0.0 1.0"/>
    <limit effort="0.0" velocity="0.0" lower="-0.7504915783575618" upper="0.6108652381980153"/>
  </joint>
  <joint name="joint36" type="revolute">
    <parent link="link28"/>
    <child link="link36"/>
    <origin xyz="0.08900000154972076 0.0 -0.08124999701976776" rpy="0.0 -0.0 0.0"/>
    <axis xyz="1.0 0.0 0.0"/>
    <limit effort="0.0" velocity="0.0" lower="-2.2165681500327987" upper="0.5235987755982988"/>
  </joint>
  <joint name="joint37" type="revolute">
    <parent link="link36"/>
    <child link="link37"/>
    <origin xyz="0.0 0.0 0.0" rpy="0.0 -0.0 0.0"/>
    <axis xyz="0.0 1.0 0.0"/>
    <limit effort="0.0" velocity="0.0" lower="-0.7853981633974483" upper="0.6981317007977318"/>
  </joint>
  <joint name="joint38" type="revolute">
    <parent link="link37"/>
    <child link="link38"/>
    <origin xyz="0.0 0.0 0.0" rpy="0.0 -0.0 0.0"/>
    <axis xyz="0.0 0.0 1.0"/>
    <limit effort="0.0" velocity="0.0" lower="-0.6981317007977318" upper="0.7853981633974483"/>
  </joint>
  <joint name="joint39" type="revolute">
    <parent link="link38"/>
    <child link="link39"/>
    <origin xyz="0.0 0.0 -0.42399999499320984" rpy="0.0 -0.0 0.0"/>
    <axis xyz="1.0 0.0 0.0"/>
    <limit effort="0.0" velocity="0.0" lower="0.0" upper="2.2689280275926285"/>
  </joint>
  <joint name="joint40" type="revolute">
    <parent link="link39"/>
    <child link="link40"/>
    <origin xyz="0.0 0.0 -0.42800000309944153" rpy="0.0 -0.0 0.0"/>
    <axis xyz="1.0 0.0 0.0"/>
    <limit effort="0.0" velocity="0.0" lower="-0.6108652381980153" upper="0.6632251157578453"/>
  </joint>
  <joint name="joint41" type="revolute">
    <parent link="link40"/>
    <child link="link41"/>
    <origin xyz="0.0 0.0 0.0" rpy="0.0 -0.0 0.0"/>
    <axis xyz="0.0 1.0 0.0"/>
    <limit effort="0.0" velocity="0.0" lower="-0.4188790204786391" upper="0.4014257279586958"/>
  </joint>
  <joint name="joint42" type="revolute">
    <parent link="link41"/>
    <child link="link42"/>
    <origin xyz="0.0 0.0 0.0" rpy="0.0 -0.0 0.0"/>
    <axis xyz="0.0 0.0 1.0"/>
    <limit effort="0.0" velocity="0.0" lower="-0.6108652381980153" upper="0.7504915783575618"/>
  </joint>

  <!-- End effector joint (fixed) -->
  <joint name="end_effector" type="fixed">
    <origin xyz="0 0 -0.4" rpy="3.1415926535 0 1.5707963267948966"/>
    <parent link="link14"/>
    <child link="end_effector_link"/>
    <axis xyz="0 0 0"/>
  </joint>

  <!-- End effector link -->
  <link name="end_effector_link">
    <inertial>
      <origin xyz="0 0 0" rpy="0 0 0"/>
      <mass value="0"/>
      <inertia ixx="0" ixy="0" ixz="0" iyy="0" iyz="0" izz="0"/>
    </inertial>
  </link>
  
</robot>
